Workbook

Sheet NHẬP ĐƠN
A1: Tên khách | B1: Tên Sp | C1: Mã SP | D1: SIZE | E1: COLOR | F1: Số lượng | G1: Giá sp | H1: NGÀY OD | I1: TRẠNG THÁI | J1: Link fb
A2: Ngọc Thuý Trần | B2: Phông trơn ngắn tay | C2: 8886 | D2: S | E2: TRẮNG | F2: 1 | G2: 1090 | H2: 46085 | I2: Đã gửi | J2: https://www.facebook.com/share/1QYxbzMHD7/?mibextid=wwXIfr
A3: Ngọc Thuý Trần | B3: Phông trơn ngắn tay | C3: 8886 | D3: S | E3: HỒNG | F3: 1 | G3: 1090 | H3: 46085 | I3: Đã gửi
A4: Uyên Lê | B4: Phông trơn ngắn tay | C4: 8886 | D4: S | E4: ĐEN | F4: 1 | G4: 1090 | H4: 46085 | I4: Đã gửi
A5: Hà Giang | B5: Phông trơn ngắn tay | C5: 8886 | D5: S | E5: ĐEN | F5: 1 | G5: 1090 | H5: 46085 | I5: Đã gửi
A6: Hà Giang | B6: Phông trơn ngắn tay | C6: 8886 | D6: S | E6: TRẮNG | F6: 1 | G6: 1090 | H6: 46085 | I6: Đã gửi
A7: Hà Giang | B7: Phông trơn ngắn tay | C7: 8886 | D7: S | E7: XÁM ĐẬM | F7: 1 | G7: 1090 | H7: 46085 | I7: Đã gửi
A8: Bùi Thị Ngọc Hân | B8: Phông trơn ngắn tay | C8: 8886 | D8: M | E8: XÁM | F8: 1 | G8: 1090 | H8: 46085 | I8: Đã xoá
A9: Trang Mẩu | B9: Phông trơn ngắn tay | C9: 8886 | D9: M | E9: NÂU | F9: 1 | G9: 1090 | H9: 46085 | I9: Đã gửi
A10: Trang Mẩu | B10: Phông trơn ngắn tay | C10: 8886 | D10: M | E10: TRẮNG | F10: 1 | G10: 1090 | H10: 46085 | I10: Đã gửi
A11: Trang Mẩu | B11: Phông trơn ngắn tay | C11: 8886 | D11: M | E11: ĐEN | F11: 1 | G11: 1090 | H11: 46085 | I11: Đã gửi
A12: Trang Mẩu | B12: Phông trơn ngắn tay | C12: 8886 | D12: M | E12: ĐỎ | F12: 1 | G12: 1090 | H12: 46085 | I12: Đã gửi
A13: Nguyễn Phương Vy | B13: Phông trơn ngắn tay | C13: 8886 | D13: M | E13: ĐEN | F13: 1 | G13: 1090 | H13: 46085 | I13: Đã gửi
A14: Nguyễn Phương Vy | B14: Phông trơn ngắn tay | C14: 8886 | D14: M | E14: TRẮNG | F14: 1 | G14: 1090 | H14: 46085 | I14: Đã gửi
... A41: Ng Hà Phương | B41: Phông trơn ngắn tay | C41: 8886 | D41: S | E41: XÁM | F41: 1 | G41: 1090 | H41: 46085 | I41: Đã gửi
A42: Nguyễn Hương | B42: Phông trơn ngắn tay | C42: 8886 | D42: S | E42: TRẮNG | F42: 1 | G42: 1090 | H42: 46085 | I42: Đã gửi | J42: https://www.facebook.com/share/17v6iyn5xx/?mibextid=wwXIfr
A43: Hương Cherry | B43: Polo lông thỏ | C43: 7859 | D43: FZ | E43: BE | F43: 1 | G43: 2100 | H43: 46085 | I43: Đã gửi
A44: Hoàng Yếnn | B44: Polo lông thỏ | C44: 7859 | D44: FZ | E44: HỒNG | F44: 1 | G44: 2100 | H44: 46085 | I44: Đã gửi
A45: Lộc Tâm | B45: Polo lông thỏ | C45: 7859 | D45: FZ | E45: HỒNG | F45: 1 | G45: 2100 | H45: 46085 | I45: Đã gửi
A46: Ngọc Hà | B46: Polo lông thỏ | C46: 7859 | D46: FZ | E46: HỒNG | F46: 1 | G46: 2100 | H46: 46085 | I46: Đã gửi
A47: Phương Nga | B47: Polo lông thỏ | C47: 7859 | D47: FZ | E47: BE | F47: 1 | G47: 2100 | H47: 46085 | I47: Đã gửi
A48: Lụa Mỹ | B48: Polo lông thỏ | C48: 7859 | D48: FZ | E48: HỒNG | F48: 1 | G48: 2100 | H48: 46085 | I48: Đã gửi
A49: Trần Thị Thu | B49: Polo lông thỏ | C49: 7859 | D49: FZ | E49: BE | F49: 1 | G49: 2100 | H49: 46085 | I49: Đã gửi
A50: Phạm Hoàn | B50: Polo lông thỏ | C50: 7859 | D50: FZ | E50: BE | F50: 1 | G50: 2100 | H50: 46085 | I50: Đã gửi
A51: Hà Oanh | B51: Polo lông thỏ | C51: 7859 | D51: FZ | E51: HỒNG | F51: 1 | G51: 2100 | H51: 46085 | I51: Đã gửi
A52: Lê Thuỳ Dương | B52: Polo lông thỏ | C52: 7859 | D52: FZ | E52: BE | F52: 1 | G52: 2100 | H52: 46085 | I52: Đã gửi
A53: Lê Thuỳ Dương | B53: Polo lông thỏ | C53: 7859 | D53: FZ | E53: HỒNG | F53: 1 | G53: 2100 | H53: 46085 | I53: Đã gửi
A54: Thuỳ Trang | B54: Polo lông thỏ | C54: 7859 | D54: FZ | E54: HỒNG | F54: 1 | G54: 2100 | H54: 46085 | I54: Đã gửi
A55: Tâm Tâm | B55: Jean xanh đậm | C55: 8865 | D55: M | E55: XANH THAN | F55: 1 | G55: 2500 | H55: 46085 | I55: Đã gửi | J55: https://www.facebook.com/share/1GzVVq96Za/?mibextid=wwXIfr
A56: Trang Minn | B56: Jean xanh đậm | C56: 8865 | D56: M | E56: XANH THAN | F56: 1 | G56: 2500 | H56: 46085 | I56: Đã gửi
A57: Phan Nhung | B57: Jean xanh đậm | C57: 8865 | D57: M | E57: XANH THAN | F57: 1 | G57: 2500 | H57: 46085 | I57: Đã gửi
A58: GiangHoang Vu | B58: Jean xanh đậm | C58: 8865 | D58: M | E58: XANH THAN | F58: 1 | G58: 2500 | H58: 46085 | I58: Đã gửi
A59: Thuỳ Trang | B59: Jean xanh đậm | C59: 8865 | D59: S | E59: XANH THAN | F59: 1 | G59: 2500 | H59: 46085 | I59: Đã gửi
A60: Trang Đoàn | B60: Jean xanh đậm | C60: 8865 | D60: M | E60: XANH THAN | F60: 1 | G60: 2500 | H60: 46085 | I60: Đã gửi
A61: Hoàng Nhật Mai | B61: Jean xanh đậm | C61: 8865 | D61: S | E61: XANH THAN | F61: 1 | G61: 2500 | H61: 46085 | I61: Đã gửi
A62: Hong Doan | B62: Jean xanh đậm | C62: 8865 | D62: S | E62: XANH THAN | F62: 2 | G62: 2500 | H62: 46085 | I62: Đã gửi
A63: Cao The | B63: Jean xanh đậm | C63: 8865 | D63: S | E63: XANH THAN | F63: 1 | G63: 2500 | H63: 46085 | I63: Đã gửi | J63: https://www.facebook.com/share/18RcCZWJ6a/?mibextid=wwXIfr
A64: Ngọc Hiền | B64: Jean xanh đậm | C64: 8865 | D64: S | E64: XANH THAN | F64: 1 | G64: 2500 | H64: 46085 | I64: Đã gửi
A65: Huyền Trang | B65: Jean xanh đậm | C65: 8865 | D65: M | E65: XANH THAN | F65: 1 | G65: 2500 | H65: 46085 | I65: Đã gửi | J65: https://www.facebook.com/share/1EJQU4nE6g/?mibextid=wwXIfr
A66: Li Ly | B66: Jean xanh đậm | C66: 8865 | D66: M | E66: XANH THAN | F66: 1 | G66: 2500 | H66: 46085 | I66: Đã gửi
...

Sheet Trang tính8

Sheet HÀNG DƯ
A1: Mã SP | B1: Size | C1: Color | D1: SL dư | E1: Trạng thái | F1: Ngày tạo
A2: 8876 | B2: M | C2: ĐEN | D2: 5 | E2: Về kho | F2: 46144
A3: 8876 | B3: S | C3: ĐEN | D3: 2 | E3: Về kho | F3: 46153
A4: 3225 | B4: M | C4: XANH THAN | D4: 1 | E4: Về kho | F4: 46153
A5: 9094 | B5: S | C5: XANH THAN | D5: 1 | E5: Về kho | F5: 46153
A6: 9094 | B6: S | C6: XÁM | D6: 1 | E6: Về kho | F6: 46153
A7: 7957 | B7: M | C7: XÁM | D7: 1 | E7: Về kho | F7: 46153
A8: M005 | B8: 39 | C8: NÂU | D8: 1 | E8: Về kho | F8: 46153
A9: M001 | B9: 35 | C9: ĐEN | D9: 1 | E9: Về kho | F9: 46153
A10: M001 | B10: 40 | C10: ĐEN | D10: 1 | E10: Về kho | F10: 46153
A11: M001 | B11: 39 | C11: ĐEN | D11: 1 | E11: Về kho | F11: 46153
A12: 6612 | B12: FZ | C12: 5 | D12: 1 | E12: Về kho | F12: 46177
A13: 1639 | B13: S | C13: CAM | D13: 1 | E13: Về kho | F13: 46176
A14: 1639 | B14: M | C14: CAM | D14: 1 | E14: Về kho | F14: 46176
A15: M007 | B15: FZ | C15: NHUNGDO | D15: 1 | E15: Về kho | F15: 46176
A16: 9094 | B16: M | C16: HỒNG | D16: 2 | E16: Về kho | F16: 46176
A17: 5007 | B17: M | C17: ĐEN | D17: 1 | E17: Chờ hàng | F17: 46178
A18: P230MTX362 | B18: 36 | C18: NÂU | D18: 2 | E18: Về kho | F18: 46178
A19: CK98118 | B19: S | C19: ĐEN | D19: 3 | E19: Về kho | F19: 46183
A20: BRA2 | B20: M | C20: TRẮNG | D20: 1 | E20: Về kho | F20: 46182
A21: M009 | B21: XL | C21: ĐEN | D21: 1 | E21: Về kho | F21: 46182
A22: M009 | B22: XL | C22: XÁM | D22: 1 | E22: Về kho | F22: 46182
A23: M014 | B23: FZ | C23: TÍM | D23: 1 | E23: Về kho | F23: 46182
A24: M012 | B24: FZ | C24: TÍM | D24: 2 | E24: Về kho | F24: 46182
A25: M012 | B25: FZ | C25: VÀNG | D25: 2 | E25: Về kho | F25: 46182
A26: 9425 | B26: M | C26: XANH THAN | D26: 2 | E26: Về kho | F26: 46182
A27: 5709 | B27: S | C27: XANH NHẠT | D27: 2 | E27: Về kho | F27: 46183
A28: 9031 | B28: M | C28: TRẮNG | D28: 1 | E28: Chờ hàng | F28: 46184
A29: 5670 | B29: S | C29: TRẮNG | D29: 2 | E29: Về kho | F29: 46184

Sheet LỊCH SỬ
A1: Tên khách | B1: Tên Sp | C1: Mã SP | D1: SIZE | E1: COLOR | F1: Số lượng | G1: Giá sp | H1: NGÀY OD | I1: TRẠNG THÁI | J1: Link fb
A2: Thuỳ Trangg | B2: Giày howell | C2: M001 | D2: 37 | E2: ĐEN | F2: 1 | G2: 1990 | H2: 46100 | I2: Đã gửi
A3: Thảo Thỏ | B3: Giày howell | C3: M001 | D3: 36 | E3: BE | F3: 1 | G3: 1990 | H3: 46100 | I3: Đã gửi
A4: Hoàng Yến | B4: Giày howell | C4: M001 | D4: 35 | E4: ĐEN | F4: 1 | G4: 1990 | H4: 46104 | I4: Đã gửi
A5: Hoàng Yến | B5: Giày howell | C5: M001 | D5: 35 | E5: ĐEN | F5: 1 | G5: 1990 | H5: 46104 | I5: Đã gửi
A6: Hoàng Yến | B6: Giày howell | C6: M001 | D6: 35 | E6: ĐEN | F6: 1 | G6: 1990 | H6: 46104 | I6: Đã gửi
A7: Hoàng Yến | B7: Giày howell | C7: M001 | D7: 35 | E7: ĐEN | F7: 1 | G7: 1990 | H7: 46104 | I7: Đã gửi
A8: Hoàng Yến | B8: Giày howell | C8: M001 | D8: 35 | E8: ĐEN | F8: 1 | G8: 1990 | H8: 46104 | I8: Đã gửi
A9: Hột Mít | B9: Giày howell | C9: M001 | D9: 39 | E9: ĐEN | F9: 1 | G9: 1990 | H9: 46110 | I9: Đã gửi | J9: https://www.facebook.com/share/1GFVuaM7ZC/
A10: Hột Mít | B10: Giày howell | C10: M001 | D10: 39 | E10: ĐEN | F10: 1 | G10: 1990 | H10: 46110 | I10: Đã gửi | J10: https://www.facebook.com/share/1GFVuaM7ZC/
A11: Hột Mít | B11: Giày howell | C11: M001 | D11: 39 | E11: ĐEN | F11: 1 | G11: 1990 | H11: 46110 | I11: Đã gửi | J11: https://www.facebook.com/share/1GFVuaM7ZC/
A12: Hột Mít | B12: Giày howell | C12: M001 | D12: 39 | E12: ĐEN | F12: 1 | G12: 1990 | H12: 46110 | I12: Đã gửi | J12: https://www.facebook.com/share/1GFVuaM7ZC/
A13: Hột Mít | B13: Giày howell | C13: M001 | D13: 39 | E13: ĐEN | F13: 1 | G13: 1990 | H13: 46110 | I13: Đã gửi | J13: https://www.facebook.com/share/1GFVuaM7ZC/
A14: Hột Mít | B14: Giày howell | C14: M001 | D14: 39 | E14: ĐEN | F14: 1 | G14: 1990 | H14: 46110 | I14: Đã gửi | J14: https://www.facebook.com/share/1GFVuaM7ZC/
A15: HằnG Em | B15: Áo dây | C15: M006 | D15: FZ | E15: TRẮNG | F15: 1 | G15: 750 | H15: 46118 | I15: Đã gửi | J15: https://www.facebook.com/share/14e2CsYrAZ6/
A16: Đàm Chinh | B16: Áo dây | C16: M006 | D16: FZ | E16: XÁM | F16: 1 | G16: 750 | H16: 46118 | I16: Đã gửi | J16: https://www.facebook.com/share/1CYRqHhKAG/
A17: Đàm Chinh | B17: Áo dây | C17: M006 | D17: FZ | E17: XÁM | F17: 1 | G17: 750 | H17: 46118 | I17: Đã gửi | J17: https://www.facebook.com/share/1CYRqHhKAG/
A18: Đàm Chinh | B18: Áo dây | C18: M006 | D18: FZ | E18: XÁM | F18: 1 | G18: 750 | H18: 46118 | I18: Đã gửi | J18: https://www.facebook.com/share/1CYRqHhKAG/
A19: Đàm Chinh | B19: Áo dây | C19: M006 | D19: FZ | E19: XÁM | F19: 1 | G19: 750 | H19: 46118 | I19: Đã gửi | J19: https://www.facebook.com/share/1CYRqHhKAG/
A20: Trang Đoàn | B20: Mũ Polo | C20: MU01 | D20: FZ | E20: BE | F20: 1 | G20: 1200 | H20: 46123 | I20: Đã gửi | J20: https://www.facebook.com/share/1CJaXPJ5aQ/
A21: Trang Đoàn | B21: Mũ Polo | C21: MU01 | D21: FZ | E21: BE | F21: 1 | G21: 1200 | H21: 46123 | I21: Đã gửi | J21: https://www.facebook.com/share/1CJaXPJ5aQ/
A22: Ng Thị Hảo | B22: Jean lửng xanh đậm | C22: 8748 | D22: S | E22: XANH THAN | F22: 1 | G22: 1800 | H22: 46125 | I22: Đã gửi
A23: Ng Thị Hảo | B23: Jean lửng xanh đậm | C23: 8748 | D23: S | E23: XANH THAN | F23: 1 | G23: 1800 | H23: 46125 | I23: Đã gửi
A24: Ng Thị Hảo | B24: Jean lửng xanh đậm | C24: 8748 | D24: S | E24: XANH THAN | F24: 1 | G24: 1800 | H24: 46125 | I24: Đã gửi
A25: Minh Trang | B25: Jean lửng xanh đậm | C25: 8748 | D25: L | E25: XANH THAN | F25: 1 | G25: 1800 | H25: 46128 | I25: Đã gửi | J25: https://www.facebook.com/share/14bDUZJAxHW/
A26: Minh Trang | B26: Jean lửng xanh đậm | C26: 8748 | D26: L | E26: XANH THAN | F26: 1 | G26: 1800 | H26: 46128 | I26: Đã gửi | J26: https://www.facebook.com/share/14bDUZJAxHW/
A27: Minh Trang | B27: Jean lửng xanh đậm | C27: 8748 | D27: L | E27: XANH THAN | F27: 1 | G27: 1800 | H27: 46128 | I27: Đã gửi | J27: https://www.facebook.com/share/14bDUZJAxHW/
A28: Minh Trang | B28: Jean lửng xanh đậm | C28: 8748 | D28: L | E28: XANH THAN | F28: 1 | G28: 1800 | H28: 46128 | I28: Đã gửi | J28: https://www.facebook.com/share/14bDUZJAxHW/
A29: Minh Trang | B29: Jean lửng xanh đậm | C29: 8748 | D29: L | E29: XANH THAN | F29: 1 | G29: 1800 | H29: 46128 | I29: Đã gửi | J29: https://www.facebook.com/share/14bDUZJAxHW/
A30: Phan Hằng | B30: Giày howell | C30: M001 | D30: 36 | E30: ĐEN | F30: 1 | G30: 1990 | H30: 46133 | I30: Đã gửi
A31: Phan Hằng | B31: Giày howell | C31: M001 | D31: 36 | E31: ĐEN | F31: 1 | G31: 1990 | H31: 46133 | I31: Đã gửi
A32: Phan Hằng | B32: Giày howell | C32: M001 | D32: 36 | E32: ĐEN | F32: 1 | G32: 1990 | H32: 46133 | I32: Đã gửi
A33: Thu Phương | B33: Giày howell | C33: M001 | D33: 36 | E33: BE | F33: 1 | G33: 1990 | H33: 46136 | I33: Đã gửi | J33: https://www.facebook.com/share/1AznU6QD5p/
A34: Ngân | B34: jeep sandal | C34: PE232WAS632 | D34: 37 | E34: TÍM | F34: 1 | G34: 6800 | H34: 46137 | I34: Đã gửi
A35: Ngân | B35: jeep sandal | C35: PE232WAS632 | D35: 37 | E35: TÍM | F35: 1 | G35: 6800 | H35: 46137 | I35: Đã gửi
A36: Hạ Hạ | B36: Giày jeep bestseller | C36: P651W13112C | D36: 37 | E36: XANH NHẠT | F36: 1 | G36: 6990 | H36: 46139 | I36: Đã gửi
A37: Hạ Hạ | B37: Giày jeep bestseller | C37: P651W13112C | D37: 37 | E37: XANH NHẠT | F37: 1 | G37: 6990 | H37: 46139 | I37: Đã gửi
A38: Trần Thị Cẩm My | B38: Sữa tắm nước hoa | C38: M013 | D38: FZ | E38: NÂU | F38: 2 | G38: 1700 | H38: 46141 | I38: Đã gửi | J38: https://www.facebook.com/share/1BKnyGxqCz/
A39: Trần Thị Cẩm My | B39: Sữa tắm nước hoa | C39: M013 | D39: FZ | E39: NÂU | F39: 2 | G39: 1700 | H39: 46141 | I39: Đã gửi | J39: https://www.facebook.com/share/1BKnyGxqCz/
A40: Trần Thị Cẩm My | B40: Sữa tắm nước hoa | C40: M013 | D40: FZ | E40: NÂU | F40: 2 | G40: 1700 | H40: 46141 | I40: Đã gửi | J40: https://www.facebook.com/share/1BKnyGxqCz/
...

Sheet KHO HÀNG
A1: Mã SP | B1: Size | C1: Color | D1: Số lượng nhập | E1: Ngày nhập | F1: Ghi chú
A2: 7398 | B2: S | C2: TRẮNG | D2: 1 | E2: 46098
A3: 7436 | B3: M | C3: XANH THAN | D3: 1 | E3: 46098
A4: 7458 | B4: S | C4: ĐEN | D4: 2 | E4: 46098
A5: 7910 | B5: M | C5: TRẮNG | D5: 1 | E5: 46098
A6: 7910 | B6: S | C6: ĐEN | D6: 1 | E6: 46098
A7: 7910 | B7: S | C7: NÂU | D7: 1 | E7: 46098
A8: 8625 | B8: S | C8: XANH THAN | D8: 4 | E8: 46098
A9: 8625 | B9: M | C9: XANH THAN | D9: 1 | E9: 46098
A10: 7398 | B10: S | C10: ĐEN | D10: 2 | E10: 46098
A11: 7398 | B11: S | C11: XÁM | D11: 1 | E11: 46098
A12: 7458 | B12: M | C12: ĐEN | D12: 3 | E12: 46098
A13: 7859 | B13: FZ | C13: HỒNG | D13: 7 | E13: 46098
... A90: 8876 | B90: S | C90: NÂU | D90: 3 | E90: 46109
A91: M001 | B91: 40 | C91: BE | D91: 1 | E91: 46109
A92: M001 | B92: 38 | C92: ĐEN | D92: 4 | E92: 46109
A93: M001 | B93: 35 | C93: BE | D93: 1 | E93: 46109
A94: M001 | B94: 39 | C94: ĐEN | D94: 4 | E94: 46109
A95: M001 | B95: 36 | C95: BE | D95: 1 | E95: 46109
A96: M001 | B96: 36 | C96: BE | D96: 2 | E96: 46109
A97: M001 | B97: 38 | C97: BE | D97: 4 | E97: 46109
A98: M001 | B98: 39 | C98: BE | D98: 1 | E98: 46109
A99: M001 | B99: 37 | C99: ĐEN | D99: 3 | E99: 46109
A100: 8748 | B100: S | C100: XANH THAN | D100: 1 | E100: 46109
A101: 8876 | B101: M | C101: TÍM | D101: 2 | E101: 46109
A102: 8521 | B102: S | C102: NÂU | D102: 1 | E102: 46111
A103: 8521 | B103: M | C103: NÂU | D103: 1 | E103: 46111
A104: 8867 | B104: S | C104: HỒNG | D104: 3 | E104: 46111
A105: 8867 | B105: S | C105: XANH THAN | D105: 2 | E105: 46111
A106: 7307 | B106: S | C106: BE | D106: 1 | E106: 46111
A107: 7307 | B107: M | C107: NÂU | D107: 1 | E107: 46111
A108: 9369 | B108: M | C108: XANH THAN | D108: 1 | E108: 46111
A109: 9369 | B109: S | C109: XANH THAN | D109: 1 | E109: 46111
A110: 7137 | B110: S | C110: XANH THAN | D110: 2 | E110: 46111
A111: M001 | B111: 37 | C111: BE | D111: 2 | E111: 46111
A112: M001 | B112: 36 | C112: BE | D112: 1 | E112: 46111
A113: M001 | B113: 39 | C113: BE | D113: 2 | E113: 46111
A114: M001 | B114: 40 | C114: BE | D114: 1 | E114: 46111
A115: M001 | B115: 35 | C115: ĐEN | D115: 2 | E115: 46111
A116: M001 | B116: 36 | C116: ĐEN | D116: 2 | E116: 46111
...

Sheet LỆNH GỬI HÀNG
A1: Tên khách | B1: Tổng hàng order | C1: Trạng thái hàng | D1: Đã gửi | E1: Ngày gửi
A2: =IFERROR(__xludf.DUMMYFUNCTION("UNIQUE(FILTER('NHẬP ĐƠN'!A2:A1501, 'NHẬP ĐƠN'!A2:A1501<>""""))"),"Ngọc Thuý Trần") -> Ngọc Thuý Trần | B2: {=MAP(A2:A1501, LAMBDA(khach, IF(khach="",, COUNTIF('NHẬP ĐƠN'!A2:A1501, khach))))} -> 14 | C2: =IFERROR(__xludf.DUMMYFUNCTION("MAP(A2:A1501, LAMBDA(khach, IF(khach="""", """", LET( ma_sp, IFERROR(FILTER('NHẬP ĐƠN'!C2:C1501, IFERROR('NHẬP ĐƠN'!A2:A1501 = khach, FALSE)), """"), IF(INDEX(ma_sp, 1) = """", ""❌ KHÔNG CÓ TRONG NHẬP ĐƠN"", LET( "&" size_sp, FILTER('NHẬP ĐƠN'!D2:D1501, IFERROR('NHẬP ĐƠN'!A2:A1501 = khach, FALSE)), color_sp, FILTER('NHẬP ĐƠN'!E2:E1501, IFERROR('NHẬP ĐƠN'!A2:A1501 = khach, FALSE)), luy_ke, FILTER('NHẬP ĐƠN'!K2:K1501, IFERROR('NHẬP ĐƠN'!A2:A1501 = "&"khach, FALSE)), so_mon_dat, ROWS(ma_sp), kiem_tra, MAP(ma_sp, size_sp, color_sp, luy_ke, LAMBDA(m, s, c, lk, LET( ton_kho, SUMIFS('KHO HÀNG'!D:D, 'KHO HÀNG'!A:A, m, 'KHO HÀNG'!B:B, s, 'KHO HÀNG'!C:C"&", c), IF(ton_kho >= lk, 1, 0) ) )), so_mon_du, SUM(kiem_tra), IF(so_mon_du = so_mon_dat, ""✅ ĐỦ HÀNG"", ""❌ THIẾU "" & (so_mon_dat - so_mon_du) & "" MÓN"") ) ) ) ) ))"),"✅ ĐỦ HÀNG") -> ✅ ĐỦ HÀNG
A3: =IFERROR(__xludf.DUMMYFUNCTION("""COMPUTED_VALUE"""),"Uyên Lê") -> Uyên Lê | B3: 6 | C3: =IFERROR(__xludf.DUMMYFUNCTION("""COMPUTED_VALUE"""),"✅ ĐỦ HÀNG") -> ✅ ĐỦ HÀNG
A4: =IFERROR(__xludf.DUMMYFUNCTION("""COMPUTED_VALUE"""),"Hà Giang") -> Hà Giang | B4: 5 | C4: =IFERROR(__xludf.DUMMYFUNCTION("""COMPUTED_VALUE"""),"✅ ĐỦ HÀNG") -> ✅ ĐỦ HÀNG
A5: =IFERROR(__xludf.DUMMYFUNCTION("""COMPUTED_VALUE"""),"Bùi Thị Ngọc Hân") -> Bùi Thị Ngọc Hân | B5: 1 | C5: =IFERROR(__xludf.DUMMYFUNCTION("""COMPUTED_VALUE"""),"✅ ĐỦ HÀNG") -> ✅ ĐỦ HÀNG
A6: =IFERROR(__xludf.DUMMYFUNCTION("""COMPUTED_VALUE"""),"Trang Mẩu") -> Trang Mẩu | B6: 11 | C6: =IFERROR(__xludf.DUMMYFUNCTION("""COMPUTED_VALUE"""),"✅ ĐỦ HÀNG") -> ✅ ĐỦ HÀNG
A7: =IFERROR(__xludf.DUMMYFUNCTION("""COMPUTED_VALUE"""),"Nguyễn Phương Vy") -> Nguyễn Phương Vy | B7: 3 | C7: =IFERROR(__xludf.DUMMYFUNCTION("""COMPUTED_VALUE"""),"✅ ĐỦ HÀNG") -> ✅ ĐỦ HÀNG
A8: =IFERROR(__xludf.DUMMYFUNCTION("""COMPUTED_VALUE"""),"Lily") -> Lily | B8: 2 | C8: =IFERROR(__xludf.DUMMYFUNCTION("""COMPUTED_VALUE"""),"✅ ĐỦ HÀNG") -> ✅ ĐỦ HÀNG
A9: =IFERROR(__xludf.DUMMYFUNCTION("""COMPUTED_VALUE"""),"Thanh Hang Huang") -> Thanh Hang Huang | B9: 2 | C9: =IFERROR(__xludf.DUMMYFUNCTION("""COMPUTED_VALUE"""),"✅ ĐỦ HÀNG") -> ✅ ĐỦ HÀNG
A10: =IFERROR(__xludf.DUMMYFUNCTION("""COMPUTED_VALUE"""),"Kim Cúc") -> Kim Cúc | B10: 2 | C10: =IFERROR(__xludf.DUMMYFUNCTION("""COMPUTED_VALUE"""),"✅ ĐỦ HÀNG") -> ✅ ĐỦ HÀNG
A11: =IFERROR(__xludf.DUMMYFUNCTION("""COMPUTED_VALUE"""),"Lê Thuỳ Dương") -> Lê Thuỳ Dương | B11: 19 | C11: =IFERROR(__xludf.DUMMYFUNCTION("""COMPUTED_VALUE"""),"✅ ĐỦ HÀNG") -> ✅ ĐỦ HÀNG
A12: =IFERROR(__xludf.DUMMYFUNCTION("""COMPUTED_VALUE"""),"Trần Kiều Giang") -> Trần Kiều Giang | B12: 2 | C12: =IFERROR(__xludf.DUMMYFUNCTION("""COMPUTED_VALUE"""),"✅ ĐỦ HÀNG") -> ✅ ĐỦ HÀNG
A13: =IFERROR(__xludf.DUMMYFUNCTION("""COMPUTED_VALUE"""),"Phạm Thị Như Ý") -> Phạm Thị Như Ý | B13: 5 | C13: =IFERROR(__xludf.DUMMYFUNCTION("""COMPUTED_VALUE"""),"✅ ĐỦ HÀNG") -> ✅ ĐỦ HÀNG
A14: =IFERROR(__xludf.DUMMYFUNCTION("""COMPUTED_VALUE"""),"Nguyễn Thu") -> Nguyễn Thu | B14: 7 | C14: =IFERROR(__xludf.DUMMYFUNCTION("""COMPUTED_VALUE"""),"✅ ĐỦ HÀNG") -> ✅ ĐỦ HÀNG
A15: =IFERROR(__xludf.DUMMYFUNCTION("""COMPUTED_VALUE"""),"Ngọc Huyền") -> Ngọc Huyền | B15: 10 | C15: =IFERROR(__xludf.DUMMYFUNCTION("""COMPUTED_VALUE"""),"✅ ĐỦ HÀNG") -> ✅ ĐỦ HÀNG
A16: =IFERROR(__xludf.DUMMYFUNCTION("""COMPUTED_VALUE"""),"Dang Minh") -> Dang Minh | B16: 13 | C16: =IFERROR(__xludf.DUMMYFUNCTION("""COMPUTED_VALUE"""),"✅ ĐỦ HÀNG") -> ✅ ĐỦ HÀNG
A17: =IFERROR(__xludf.DUMMYFUNCTION("""COMPUTED_VALUE"""),"Trần Thị Thu") -> Trần Thị Thu | B17: 4 | C17: =IFERROR(__xludf.DUMMYFUNCTION("""COMPUTED_VALUE"""),"✅ ĐỦ HÀNG") -> ✅ ĐỦ HÀNG
A18: =IFERROR(__xludf.DUMMYFUNCTION("""COMPUTED_VALUE"""),"Bích Thuỷ") -> Bích Thuỷ | B18: 2 | C18: =IFERROR(__xludf.DUMMYFUNCTION("""COMPUTED_VALUE"""),"✅ ĐỦ HÀNG") -> ✅ ĐỦ HÀNG
A19: =IFERROR(__xludf.DUMMYFUNCTION("""COMPUTED_VALUE"""),"Vũ Hà Thu") -> Vũ Hà Thu | B19: 3 | C19: =IFERROR(__xludf.DUMMYFUNCTION("""COMPUTED_VALUE"""),"✅ ĐỦ HÀNG") -> ✅ ĐỦ HÀNG
A20: =IFERROR(__xludf.DUMMYFUNCTION("""COMPUTED_VALUE"""),"Ng Hà Phương") -> Ng Hà Phương | B20: 4 | C20: =IFERROR(__xludf.DUMMYFUNCTION("""COMPUTED_VALUE"""),"✅ ĐỦ HÀNG") -> ✅ ĐỦ HÀNG
A21: =IFERROR(__xludf.DUMMYFUNCTION("""COMPUTED_VALUE"""),"Nguyễn Hương") -> Nguyễn Hương | B21: 7 | C21: =IFERROR(__xludf.DUMMYFUNCTION("""COMPUTED_VALUE"""),"✅ ĐỦ HÀNG") -> ✅ ĐỦ HÀNG
A22: =IFERROR(__xludf.DUMMYFUNCTION("""COMPUTED_VALUE"""),"Hương Cherry") -> Hương Cherry | B22: 1 | C22: =IFERROR(__xludf.DUMMYFUNCTION("""COMPUTED_VALUE"""),"✅ ĐỦ HÀNG") -> ✅ ĐỦ HÀNG
A23: =IFERROR(__xludf.DUMMYFUNCTION("""COMPUTED_VALUE"""),"Hoàng Yếnn") -> Hoàng Yếnn | B23: 8 | C23: =IFERROR(__xludf.DUMMYFUNCTION("""COMPUTED_VALUE"""),"✅ ĐỦ HÀNG") -> ✅ ĐỦ HÀNG
A24: =IFERROR(__xludf.DUMMYFUNCTION("""COMPUTED_VALUE"""),"Lộc Tâm") -> Lộc Tâm | B24: 6 | C24: =IFERROR(__xludf.DUMMYFUNCTION("""COMPUTED_VALUE"""),"✅ ĐỦ HÀNG") -> ✅ ĐỦ HÀNG
A25: =IFERROR(__xludf.DUMMYFUNCTION("""COMPUTED_VALUE"""),"Ngọc Hà") -> Ngọc Hà | B25: 16 | C25: =IFERROR(__xludf.DUMMYFUNCTION("""COMPUTED_VALUE"""),"✅ ĐỦ HÀNG") -> ✅ ĐỦ HÀNG
A26: =IFERROR(__xludf.DUMMYFUNCTION("""COMPUTED_VALUE"""),"Phương Nga") -> Phương Nga | B26: 5 | C26: =IFERROR(__xludf.DUMMYFUNCTION("""COMPUTED_VALUE"""),"✅ ĐỦ HÀNG") -> ✅ ĐỦ HÀNG
A27: =IFERROR(__xludf.DUMMYFUNCTION("""COMPUTED_VALUE"""),"Lụa Mỹ") -> Lụa Mỹ | B27: 2 | C27: =IFERROR(__xludf.DUMMYFUNCTION("""COMPUTED_VALUE"""),"✅ ĐỦ HÀNG") -> ✅ ĐỦ HÀNG | D27: Da gui | E27: 19:24:41 18/3/2026
A28: =IFERROR(__xludf.DUMMYFUNCTION("""COMPUTED_VALUE"""),"Phạm Hoàn") -> Phạm Hoàn | B28: 5 | C28: =IFERROR(__xludf.DUMMYFUNCTION("""COMPUTED_VALUE"""),"✅ ĐỦ HÀNG") -> ✅ ĐỦ HÀNG | D28: Da gui | E28: 16:06:00 21/3/2026
A29: =IFERROR(__xludf.DUMMYFUNCTION("""COMPUTED_VALUE"""),"Hà Oanh") -> Hà Oanh | B29: 3 | C29: =IFERROR(__xludf.DUMMYFUNCTION("""COMPUTED_VALUE"""),"✅ ĐỦ HÀNG") -> ✅ ĐỦ HÀNG | D29: Da gui | E29: 19:24:44 18/3/2026
A30: =IFERROR(__xludf.DUMMYFUNCTION("""COMPUTED_VALUE"""),"Thuỳ Trang") -> Thuỳ Trang | B30: 8 | C30: =IFERROR(__xludf.DUMMYFUNCTION("""COMPUTED_VALUE"""),"✅ ĐỦ HÀNG") -> ✅ ĐỦ HÀNG
A31: =IFERROR(__xludf.DUMMYFUNCTION("""COMPUTED_VALUE"""),"Tâm Tâm") -> Tâm Tâm | B31: 3 | C31: =IFERROR(__xludf.DUMMYFUNCTION("""COMPUTED_VALUE"""),"✅ ĐỦ HÀNG") -> ✅ ĐỦ HÀNG
A32: =IFERROR(__xludf.DUMMYFUNCTION("""COMPUTED_VALUE"""),"Trang Minn") -> Trang Minn | B32: 2 | C32: =IFERROR(__xludf.DUMMYFUNCTION("""COMPUTED_VALUE"""),"✅ ĐỦ HÀNG") -> ✅ ĐỦ HÀNG
A33: =IFERROR(__xludf.DUMMYFUNCTION("""COMPUTED_VALUE"""),"Phan Nhung ") -> Phan Nhung | B33: 2 | C33: =IFERROR(__xludf.DUMMYFUNCTION("""COMPUTED_VALUE"""),"✅ ĐỦ HÀNG") -> ✅ ĐỦ HÀNG
A34: =IFERROR(__xludf.DUMMYFUNCTION("""COMPUTED_VALUE"""),"GiangHoang Vu") -> GiangHoang Vu | B34: 1 | C34: =IFERROR(__xludf.DUMMYFUNCTION("""COMPUTED_VALUE"""),"✅ ĐỦ HÀNG") -> ✅ ĐỦ HÀNG
A35: =IFERROR(__xludf.DUMMYFUNCTION("""COMPUTED_VALUE"""),"Trang Đoàn") -> Trang Đoàn | B35: 11 | C35: =IFERROR(__xludf.DUMMYFUNCTION("""COMPUTED_VALUE"""),"✅ ĐỦ HÀNG") -> ✅ ĐỦ HÀNG
A36: =IFERROR(__xludf.DUMMYFUNCTION("""COMPUTED_VALUE"""),"Hoàng Nhật Mai") -> Hoàng Nhật Mai | B36: 3 | C36: =IFERROR(__xludf.DUMMYFUNCTION("""COMPUTED_VALUE"""),"✅ ĐỦ HÀNG") -> ✅ ĐỦ HÀNG
A37: =IFERROR(__xludf.DUMMYFUNCTION("""COMPUTED_VALUE"""),"Hong Doan") -> Hong Doan | B37: 8 | C37: =IFERROR(__xludf.DUMMYFUNCTION("""COMPUTED_VALUE"""),"✅ ĐỦ HÀNG") -> ✅ ĐỦ HÀNG
A38: =IFERROR(__xludf.DUMMYFUNCTION("""COMPUTED_VALUE"""),"Cao The") -> Cao The | B38: 1 | C38: =IFERROR(__xludf.DUMMYFUNCTION("""COMPUTED_VALUE"""),"✅ ĐỦ HÀNG") -> ✅ ĐỦ HÀNG
A39: =IFERROR(__xludf.DUMMYFUNCTION("""COMPUTED_VALUE"""),"Ngọc Hiền") -> Ngọc Hiền | B39: 8 | C39: =IFERROR(__xludf.DUMMYFUNCTION("""COMPUTED_VALUE"""),"✅ ĐỦ HÀNG") -> ✅ ĐỦ HÀNG
A40: =IFERROR(__xludf.DUMMYFUNCTION("""COMPUTED_VALUE"""),"Huyền Trang") -> Huyền Trang | B40: 11 | C40: =IFERROR(__xludf.DUMMYFUNCTION("""COMPUTED_VALUE"""),"✅ ĐỦ HÀNG") -> ✅ ĐỦ HÀNG
...

Sheet CATALOG
A1: Mã SP | B1: Tên SP | C1: Giá bán | D1: Giá nhập | E1: Lợi nhuận/SP | F1: Margin % | G1: Size | H1: Màu | I1: Đã bán | J1: Loại | K1: Cột 1
A2: M006 | B2: Áo dây | C2: 750 | D2: 350 | E2: 400 | F2: 0.53333333 | G2: FZ | H2: BE,TRẮNG,XÁM,ĐEN | I2: 129 | J2: Áo | K2: M006.jpg
A3: 8876 | B3: Ba Lỗ có mút | C3: 990 | D3: 500 | E3: 490 | F3: 0.49494949 | G3: M,S | H3: HỒNG,NÂU,TRẮNG,TÍM,ĐEN,ĐỎ | I3: 70 | J3: Áo
A4: M001 | B4: Giày howell | C4: 1990 | D4: 1340 | E4: 650 | F4: 0.32663317 | G4: 35,36,37,38,39,40 | H4: BE,ĐEN | I4: 67 | J4: Giày
A5: 8748 | B5: Jean lửng xanh đậm | C5: 1800 | D5: 1400 | E5: 400 | F5: 0.22222222 | G5: L,M,S | H5: XANH THAN | I5: 55 | J5: Quần
A6: 8740 | B6: Trắng xinh | C6: 1600 | D6: 1000 | E6: 600 | F6: 0.375 | G6: M,S | H6: BE,TRẮNG | I6: 45 | J6: Khác
A7: 8886 | B7: Phông trơn ngắn tay | C7: 1090 | D7: 650 | E7: 610 | F7: 0.55963303 | G7: M,S | H7: HỒNG,NÂU,TRẮNG,XÁM,XÁM ĐẬM,ĐEN,ĐỎ | I7: 41 | J7: Áo
A8: 81813 | B8: Phông giấy DM | C8: 1100 | D8: 600 | E8: 525 | F8: 0.47727273 | G8: FZ | H8: HỒNG,TRẮNG,VÀNG,XANH NHẠT,XÁM,ĐEN,ĐỎ | I8: 33 | J8: Áo
A9: 8865 | B9: Jean xanh đậm | C9: 2500 | D9: 2000 | E9: 500 | F9: 0.2 | G9: L,M,S | H9: XANH THAN | I9: 21 | J9: Quần
A10: 9369 | B10: Jean đậm 95cm | C10: 2600 | D10: 2000 | E10: 600 | F10: 0.23076923 | G10: M,S | H10: XANH THAN | I10: 20 | J10: Quần
A11: 8867 | B11: Phông ngựa | C11: 1200 | D11: 700 | E11: 500 | F11: 0.41666667 | G11: M,S | H11: HỒNG,TRẮNG,XANH THAN,XÁM,ĐEN | I11: 17 | J11: Áo
A12: 8319 | B12: Quần giả váy xanh | C12: 1900 | D12: 1420 | E12: 480 | F12: 0.25263158 | G12: M,S | H12: XANH THAN | I12: 15 | J12: Quần
A13: 7957 | B13: Đùi sơ mi | C13: 1400 | D13: 900 | E13: 900 | F13: 0.64285714 | G13: M,S | H13: TRẮNG,XÁM,ĐEN | I13: 13 | J13: Quần
A14: 5709 | B14: Jean EN&ER | C14: 2350 | D14: 1650 | E14: 700 | F14: 0.29787234 | G14: L,M,S | H14: XANH NHẠT | I14: 12 | J14: Quần
A15: 9094 | B15: Bộ Nỉ | C15: 2400 | D15: 1700 | E15: 700 | F15: 0.29166667 | G15: M,S | H15: HỒNG,XANH THAN,XÁM | I15: 12 | J15: Set/Bộ
A16: 7249 | B16: Jean rộng xanh | C16: 2300 | D16: 1800 | E16: 1800 | F16: 0.7826087 | G16: M,S | H16: XANH THAN | I16: 9 | J16: Quần
... A19: 9140 | B19: Hở vai | C19: 1500 | D19: 900 | E19: 600 | F19: 0.4 | G19: M,S | H19: ĐEN,ĐỎ | I19: 6 | J19: Áo
A20: M005 | B20: Giày Love | C20: 2350 | D20: 1750 | E20: 2350 | F20: 0 | G20: 35,36,37,38,39,40 | H20: BE,NÂU,ĐEN | I20: 6 | J20: Giày
A21: 7458 | B21: Set áo trễ vai | C21: 1600 | D21: 1100 | E21: 1100 | F21: 0.6875 | G21: M,S | H21: ĐEN | I21: 4 | J21: Áo
A22: 8625 | B22: Trễ vai xanh | C22: 1550 | D22: 1050 | E22: 1050 | F22: 0.67741935 | G22: M,S | H22: XANH THAN | I22: 4 | J22: Áo
A23: 8514 | B23: Áo Ren | C23: 1200 | D23: 700 | E23: 700 | F23: 0.58333333 | G23: M,S | H23: BE | I23: 3 | J23: Áo
A24: 7137 | B24: Jean xanh loe | C24: 2500 | D24: 2000 | E24: 1920 | F24: 0.768 | G24: S | H24: XANH THAN | I24: 2 | J24: Quần
A25: 7307 | B25: Loe nâu | C25: 2300 | D25: 1800 | E25: 1800 | F25: 0.7826087 | G25: M,S | H25: BE,NÂU | I25: 2 | J25: Quần
A26: 8521 | B26: Jean Rộng Nâu | C26: 2400 | D26: 1900 | E26: 1930 | F26: 0.80416667 | G26: M,S | H26: NÂU | I26: 2 | J26: Quần
A27: M003 | B27: Đồ ngủ | C27: 1290 | D27: 800 | E27: 790 | F27: 0.6124031 | G27: L | H27: ĐEN | I27: 2 | J27: Set/Bộ
A29: MU01 | B29: Mũ Polo | C29: 1200 | D29: 650 | E29: 550 | F29: 0.45833333 | H29: NÂU NHẠT,BE,NÂU,HỒNG | I29: 0 | J29: Khác
A30: TRA1 | B30: Trà Táo Đỏ | C30: 1390 | D30: 890 | E30: 500 | F30: 0.35971223 | I30: 0 | J30: Khác
A31: 8897 | B31: Áo trễ vai nơ | C31: 1200 | D31: 730 | E31: 470 | F31: 0.39166667 | G31: S,M | H31: TRẮNG | I31: 0 | J31: Áo
A32: BRA4 | B32: Bra set số 4 | C32: 1990 | D32: 1150 | E32: 840 | F32: 0.42211055 | I32: 0 | J32: Áo
A33: CHIP1 | B33: Set 10 quần lót | C33: 1550 | D33: 1050 | E33: 500 | F33: 0.32258065 | I33: 0 | J33: Quần
A34: BRA10 | B34: Set bra số 10 | C34: 1990 | D34: 1150 | E34: 840 | F34: 0.42211055 | I34: 0 | J34: Áo
A35: 9091 | B35: Quần đùi jean | C35: 1950 | D35: 1300 | E35: 650 | F35: 0.33333333 | G35: S,M,L | H35: XANH THAN | I35: 0 | J35: Quần
A36: 8116 | B36: Quần jean trơn | C36: 2490 | D36: 1700 | E36: 790 | F36: 0.31726908 | G36: S,M,L | H36: XANH THAN, TRẮNG | I36: 0 | J36: Quần
A37: 8558 | B37: Thun trơn có mút | C37: 1390 | D37: 790 | E37: 600 | F37: 0.43165468 | I37: 0 | J37: Áo
A38: M007 | B38: TÊN KHÁCH | C38: 1 | D38: 0 | E38: 1 | F38: 0 | I38: 0
A39: 9258 | B39: Quần jean khuy túi | C39: 2450 | D39: 1750 | E39: 700 | F39: 0.28571429 | I39: 0 | J39: Quần
A40: 8825 | B40: Áo chấm bi | C40: 1450 | D40: 800 | E40: 650 | F40: 0.44827586 | G40: S,M | H40: ĐEN, TRẮNG | I40: 0 | J40: Áo
A41: GIAY1 | B41: Giày bệt đính hoa | C41: 2200 | D41: 1500 | E41: 700 | F41: 0.31818182 | I41: 0 | K41: https://drive.google.com/uc?export=view&id=1gRZGgsaAlixTqG-fw_CaTSxsDz7UJNYp
A42: M008 | B42: Áo chống nắng Catkaiser | C42: 1650 | D42: 1000 | E42: 650 | F42: 0.39393939 | I42: 0 | K42: https://drive.google.com/uc?export=view&id=1qFN_ZPeHCdAPmzweF-E1DPzUDXD4-E0V
A43: GIAY2 | B43: Dép xỏ ngón | C43: 1950 | D43: 1300 | E43: 650 | F43: 0.33333333 | I43: 0
...

Sheet THỐNG KÊ
A1: 📊 THỐNG KÊ
B3: CHỈ SỐ | C3: GIÁ TRỊ
A4: 📋 | B4: Tổng đơn | C4: =COUNTIFS('NHẬP ĐƠN'!A2:A1000,"<>",'NHẬP ĐƠN'!I2:I1000,"<>Đã xoá") -> 938
A5: 💰 | B5: Doanh thu (¥) | C5: =SUMPRODUCT(('NHẬP ĐƠN'!I$2:I$1000<>"Đã xoá")*('NHẬP ĐƠN'!G$2:G$1000)*('NHẬP ĐƠN'!F$2:F$1000)) -> 1459900
A6: 📈 | B6: Lợi nhuận (¥) | C6: =SUMPRODUCT(('NHẬP ĐƠN'!I$2:I$1000<>"Đã xoá")*('NHẬP ĐƠN'!G$2:G$1000-IFERROR(VLOOKUP('NHẬP ĐƠN'!C$2:C$1000,CATALOG!A:D,4,FALSE),0))*('NHẬP ĐƠN'!F$2:F$1000)) -> 618320
A7: 🚚 | B7: Về kho | C7: =COUNTIF('NHẬP ĐƠN'!I2:I1000,"Về kho") -> 5
A8: ✅ | B8: Đã gửi | C8: =COUNTIF('NHẬP ĐƠN'!I2:I1000,"Đã gửi") -> 933
B10: TRẠNG THÁI | C10: SỐ
A11: ⚪ | B11: Chưa đặt | C11: =COUNTIF('NHẬP ĐƠN'!I2:I1000,"CHƯA ĐẶT") -> 0
A12: 🟡 | B12: Chờ hàng | C12: =COUNTIF('NHẬP ĐƠN'!I2:I1000,"Chờ hàng") -> 0
A13: 🟣 | B13: Đang ship | C13: =COUNTIF('NHẬP ĐƠN'!I2:I1000,"Đang ship") -> 0
A14: 🔵 | B14: Về kho | C14: =COUNTIF('NHẬP ĐƠN'!I2:I1000,"Về kho") -> 5
A15: 🟢 | B15: Đã gửi | C15: =COUNTIF('NHẬP ĐƠN'!I2:I1000,"Đã gửi") -> 933

Sheet KHÁCH HÀNG
A1: Tên khách | B1: Số đơn | C1: Tổng SL | D1: Doanh thu (¥) | E1: Giá TB | F1: Link FB | G1: Hạng | H1: 〒 | I1: 都道府県 | J1: 市区町村 | K1: 番地 | L1: 電話 | M1: Link FB
A2: =IFERROR(__xludf.DUMMYFUNCTION("SORT(UNIQUE(FILTER('NHẬP ĐƠN'!A2:A661, 'NHẬP ĐƠN'!A2:A661<>"""", 'NHẬP ĐƠN'!I2:I661<>""Đã xoá"")))"),"#REF!") -> #REF! | B2: =IF(A2="","",COUNTIFS('NHẬP ĐƠN'!A:A,A2,'NHẬP ĐƠN'!I:I,"<>Đã xoá")) -> #REF! | C2: =IF(A2="","",SUMPRODUCT(('NHẬP ĐƠN'!A$2:A$1000=A2)*('NHẬP ĐƠN'!I$2:I$1000<>"Đã xoá")*('NHẬP ĐƠN'!F$2:F$1000))) -> #REF! | D2: =IF(A2="","",SUMPRODUCT(('NHẬP ĐƠN'!A$2:A$1000=A2)*('NHẬP ĐƠN'!I$2:I$1000<>"Đã xoá")*('NHẬP ĐƠN'!G$2:G$1000)*('NHẬP ĐƠN'!F$2:F$1000))) -> #REF! | E2: =IF(B2>0,D2/B2,"") -> #REF! | F2: =IFERROR(VLOOKUP(A2,'NHẬP ĐƠN'!A:J,10,FALSE),"") | G2: =IF(A2="","",IF(OR(D2>=10000,B2>=5),"⭐ VIP",IF(B2>=3,"💎 Thân thiết","👤 Thường"))) -> #REF! | H2: 660-0085 | I2: 兵庫県 | J2: 尼崎市 | K2: 元浜町5-46-5 ( Kurahashi)
B3: =IF(A3="","",COUNTIFS('NHẬP ĐƠN'!A:A,A3,'NHẬP ĐƠN'!I:I,"<>Đã xoá")) | C3: =IF(A3="","",SUMPRODUCT(('NHẬP ĐƠN'!A$2:A$1000=A3)*('NHẬP ĐƠN'!I$2:I$1000<>"Đã xoá")*('NHẬP ĐƠN'!F$2:F$1000))) | D3: =IF(A3="","",SUMPRODUCT(('NHẬP ĐƠN'!A$2:A$1000=A3)*('NHẬP ĐƠN'!I$2:I$1000<>"Đã xoá")*('NHẬP ĐƠN'!G$2:G$1000)*('NHẬP ĐƠN'!F$2:F$1000))) | E3: =IF(B3>0,D3/B3,"") -> #DIV/0! | F3: =IFERROR(VLOOKUP(A3,'NHẬP ĐƠN'!A:J,10,FALSE),"") | G3: =IF(A3="","",IF(OR(D3>=10000,B3>=5),"⭐ VIP",IF(B3>=3,"💎 Thân thiết","👤 Thường"))) | H3: 486-0932 | I3: 愛知県 | J3: 春日井市 | K3: 松河戸町4-6-5 サンシャイン松河202
B4: =IF(A4="","",COUNTIFS('NHẬP ĐƠN'!A:A,A4,'NHẬP ĐƠN'!I:I,"<>Đã xoá")) | C4: =IF(A4="","",SUMPRODUCT(('NHẬP ĐƠN'!A$2:A$1000=A4)*('NHẬP ĐƠN'!I$2:I$1000<>"Đã xoá")*('NHẬP ĐƠN'!F$2:F$1000))) | D4: =IF(A4="","",SUMPRODUCT(('NHẬP ĐƠN'!A$2:A$1000=A4)*('NHẬP ĐƠN'!I$2:I$1000<>"Đã xoá")*('NHẬP ĐƠN'!G$2:G$1000)*('NHẬP ĐƠN'!F$2:F$1000))) | E4: =IF(B4>0,D4/B4,"") -> #DIV/0! | F4: =IFERROR(VLOOKUP(A4,'NHẬP ĐƠN'!A:J,10,FALSE),"") | G4: =IF(A4="","",IF(OR(D4>=10000,B4>=5),"⭐ VIP",IF(B4>=3,"💎 Thân thiết","👤 Thường")))
B5: =IF(A5="","",COUNTIFS('NHẬP ĐƠN'!A:A,A5,'NHẬP ĐƠN'!I:I,"<>Đã xoá")) | C5: =IF(A5="","",SUMPRODUCT(('NHẬP ĐƠN'!A$2:A$1000=A5)*('NHẬP ĐƠN'!I$2:I$1000<>"Đã xoá")*('NHẬP ĐƠN'!F$2:F$1000))) | D5: =IF(A5="","",SUMPRODUCT(('NHẬP ĐƠN'!A$2:A$1000=A5)*('NHẬP ĐƠN'!I$2:I$1000<>"Đã xoá")*('NHẬP ĐƠN'!G$2:G$1000)*('NHẬP ĐƠN'!F$2:F$1000))) | E5: =IF(B5>0,D5/B5,"") -> #DIV/0! | F5: =IFERROR(VLOOKUP(A5,'NHẬP ĐƠN'!A:J,10,FALSE),"") | G5: =IF(A5="","",IF(OR(D5>=10000,B5>=5),"⭐ VIP",IF(B5>=3,"💎 Thân thiết","👤 Thường")))
B6: =IF(A6="","",COUNTIFS('NHẬP ĐƠN'!A:A,A6,'NHẬP ĐƠN'!I:I,"<>Đã xoá")) | C6: =IF(A6="","",SUMPRODUCT(('NHẬP ĐƠN'!A$2:A$1000=A6)*('NHẬP ĐƠN'!I$2:I$1000<>"Đã xoá")*('NHẬP ĐƠN'!F$2:F$1000))) | D6: =IF(A6="","",SUMPRODUCT(('NHẬP ĐƠN'!A$2:A$1000=A6)*('NHẬP ĐƠN'!I$2:I$1000<>"Đã xoá")*('NHẬP ĐƠN'!G$2:G$1000)*('NHẬP ĐƠN'!F$2:F$1000))) | E6: =IF(B6>0,D6/B6,"") -> #DIV/0! | F6: =IFERROR(VLOOKUP(A6,'NHẬP ĐƠN'!A:J,10,FALSE),"") | G6: =IF(A6="","",IF(OR(D6>=10000,B6>=5),"⭐ VIP",IF(B6>=3,"💎 Thân thiết","👤 Thường")))
B7: =IF(A7="","",COUNTIFS('NHẬP ĐƠN'!A:A,A7,'NHẬP ĐƠN'!I:I,"<>Đã xoá")) | C7: =IF(A7="","",SUMPRODUCT(('NHẬP ĐƠN'!A$2:A$1000=A7)*('NHẬP ĐƠN'!I$2:I$1000<>"Đã xoá")*('NHẬP ĐƠN'!F$2:F$1000))) | D7: =IF(A7="","",SUMPRODUCT(('NHẬP ĐƠN'!A$2:A$1000=A7)*('NHẬP ĐƠN'!I$2:I$1000<>"Đã xoá")*('NHẬP ĐƠN'!G$2:G$1000)*('NHẬP ĐƠN'!F$2:F$1000))) | E7: =IF(B7>0,D7/B7,"") -> #DIV/0! | F7: =IFERROR(VLOOKUP(A7,'NHẬP ĐƠN'!A:J,10,FALSE),"") | G7: =IF(A7="","",IF(OR(D7>=10000,B7>=5),"⭐ VIP",IF(B7>=3,"💎 Thân thiết","👤 Thường"))) | H7: 289-2102 | I7: 千葉県 | J7: 匝瑳市 | K7: 椿1473-1 カンプ.ノウA102号 | L7: 8080359847
B8: =IF(A8="","",COUNTIFS('NHẬP ĐƠN'!A:A,A8,'NHẬP ĐƠN'!I:I,"<>Đã xoá")) | C8: =IF(A8="","",SUMPRODUCT(('NHẬP ĐƠN'!A$2:A$1000=A8)*('NHẬP ĐƠN'!I$2:I$1000<>"Đã xoá")*('NHẬP ĐƠN'!F$2:F$1000))) | D8: =IF(A8="","",SUMPRODUCT(('NHẬP ĐƠN'!A$2:A$1000=A8)*('NHẬP ĐƠN'!I$2:I$1000<>"Đã xoá")*('NHẬP ĐƠN'!G$2:G$1000)*('NHẬP ĐƠN'!F$2:F$1000))) | E8: =IF(B8>0,D8/B8,"") -> #DIV/0! | F8: =IFERROR(VLOOKUP(A8,'NHẬP ĐƠN'!A:J,10,FALSE),"") | G8: =IF(A8="","",IF(OR(D8>=10000,B8>=5),"⭐ VIP",IF(B8>=3,"💎 Thân thiết","👤 Thường")))
B9: =IF(A9="","",COUNTIFS('NHẬP ĐƠN'!A:A,A9,'NHẬP ĐƠN'!I:I,"<>Đã xoá")) | C9: =IF(A9="","",SUMPRODUCT(('NHẬP ĐƠN'!A$2:A$1000=A9)*('NHẬP ĐƠN'!I$2:I$1000<>"Đã xoá")*('NHẬP ĐƠN'!F$2:F$1000))) | D9: =IF(A9="","",SUMPRODUCT(('NHẬP ĐƠN'!A$2:A$1000=A9)*('NHẬP ĐƠN'!I$2:I$1000<>"Đã xoá")*('NHẬP ĐƠN'!G$2:G$1000)*('NHẬP ĐƠN'!F$2:F$1000))) | E9: =IF(B9>0,D9/B9,"") -> #DIV/0! | F9: =IFERROR(VLOOKUP(A9,'NHẬP ĐƠN'!A:J,10,FALSE),"") | G9: =IF(A9="","",IF(OR(D9>=10000,B9>=5),"⭐ VIP",IF(B9>=3,"💎 Thân thiết","👤 Thường"))) | H9: 270-0032 | I9: 千葉県 | J9: 松戸市 | K9: 北2丁目11-1 ファミールハイツ3号棟 802 | L9: 8073500318
B10: =IF(A10="","",COUNTIFS('NHẬP ĐƠN'!A:A,A10,'NHẬP ĐƠN'!I:I,"<>Đã xoá")) | C10: =IF(A10="","",SUMPRODUCT(('NHẬP ĐƠN'!A$2:A$1000=A10)*('NHẬP ĐƠN'!I$2:I$1000<>"Đã xoá")*('NHẬP ĐƠN'!F$2:F$1000))) | D10: =IF(A10="","",SUMPRODUCT(('NHẬP ĐƠN'!A$2:A$1000=A10)*('NHẬP ĐƠN'!I$2:I$1000<>"Đã xoá")*('NHẬP ĐƠN'!G$2:G$1000)*('NHẬP ĐƠN'!F$2:F$1000))) | E10: =IF(B10>0,D10/B10,"") -> #DIV/0! | F10: =IFERROR(VLOOKUP(A10,'NHẬP ĐƠN'!A:J,10,FALSE),"") | G10: =IF(A10="","",IF(OR(D10>=10000,B10>=5),"⭐ VIP",IF(B10>=3,"💎 Thân thiết","👤 Thường"))) | H10: 545-0001 | I10: 大阪府 | J10: 大阪市阿倍野区 | K10: 天王寺町北２丁目12-2キッポ天王寺北202号 | L10: 9030991196
B11: =IF(A11="","",COUNTIFS('NHẬP ĐƠN'!A:A,A11,'NHẬP ĐƠN'!I:I,"<>Đã xoá")) | C11: =IF(A11="","",SUMPRODUCT(('NHẬP ĐƠN'!A$2:A$1000=A11)*('NHẬP ĐƠN'!I$2:I$1000<>"Đã xoá")*('NHẬP ĐƠN'!F$2:F$1000))) | D11: =IF(A11="","",SUMPRODUCT(('NHẬP ĐƠN'!A$2:A$1000=A11)*('NHẬP ĐƠN'!I$2:I$1000<>"Đã xoá")*('NHẬP ĐƠN'!G$2:G$1000)*('NHẬP ĐƠN'!F$2:F$1000))) | E11: =IF(B11>0,D11/B11,"") -> #DIV/0! | F11: =IFERROR(VLOOKUP(A11,'NHẬP ĐƠN'!A:J,10,FALSE),"") | G11: =IF(A11="","",IF(OR(D11>=10000,B11>=5),"⭐ VIP",IF(B11>=3,"💎 Thân thiết","👤 Thường")))
B12: =IF(A12="","",COUNTIFS('NHẬP ĐƠN'!A:A,A12,'NHẬP ĐƠN'!I:I,"<>Đã xoá")) | C12: =IF(A12="","",SUMPRODUCT(('NHẬP ĐƠN'!A$2:A$1000=A12)*('NHẬP ĐƠN'!I$2:I$1000<>"Đã xoá")*('NHẬP ĐƠN'!F$2:F$1000))) | D12: =IF(A12="","",SUMPRODUCT(('NHẬP ĐƠN'!A$2:A$1000=A12)*('NHẬP ĐƠN'!I$2:I$1000<>"Đã xoá")*('NHẬP ĐƠN'!G$2:G$1000)*('NHẬP ĐƠN'!F$2:F$1000))) | E12: =IF(B12>0,D12/B12,"") -> #DIV/0! | F12: =IFERROR(VLOOKUP(A12,'NHẬP ĐƠN'!A:J,10,FALSE),"") | G12: =IF(A12="","",IF(OR(D12>=10000,B12>=5),"⭐ VIP",IF(B12>=3,"💎 Thân thiết","👤 Thường"))) | H12: 134-0081 | I12: 東京都 | J12: 江戸川区 | K12: 2-11-21 ジャパンエクステージ203
B13: =IF(A13="","",COUNTIFS('NHẬP ĐƠN'!A:A,A13,'NHẬP ĐƠN'!I:I,"<>Đã xoá")) | C13: =IF(A13="","",SUMPRODUCT(('NHẬP ĐƠN'!A$2:A$1000=A13)*('NHẬP ĐƠN'!I$2:I$1000<>"Đã xoá")*('NHẬP ĐƠN'!F$2:F$1000))) | D13: =IF(A13="","",SUMPRODUCT(('NHẬP ĐƠN'!A$2:A$1000=A13)*('NHẬP ĐƠN'!I$2:I$1000<>"Đã xoá")*('NHẬP ĐƠN'!G$2:G$1000)*('NHẬP ĐƠN'!F$2:F$1000))) | E13: =IF(B13>0,D13/B13,"") -> #DIV/0! | F13: =IFERROR(VLOOKUP(A13,'NHẬP ĐƠN'!A:J,10,FALSE),"") | G13: =IF(A13="","",IF(OR(D13>=10000,B13>=5),"⭐ VIP",IF(B13>=3,"💎 Thân thiết","👤 Thường")))
B14: =IF(A14="","",COUNTIFS('NHẬP ĐƠN'!A:A,A14,'NHẬP ĐƠN'!I:I,"<>Đã xoá")) | C14: =IF(A14="","",SUMPRODUCT(('NHẬP ĐƠN'!A$2:A$1000=A14)*('NHẬP ĐƠN'!I$2:I$1000<>"Đã xoá")*('NHẬP ĐƠN'!F$2:F$1000))) | D14: =IF(A14="","",SUMPRODUCT(('NHẬP ĐƠN'!A$2:A$1000=A14)*('NHẬP ĐƠN'!I$2:I$1000<>"Đã xoá")*('NHẬP ĐƠN'!G$2:G$1000)*('NHẬP ĐƠN'!F$2:F$1000))) | E14: =IF(B14>0,D14/B14,"") -> #DIV/0! | F14: =IFERROR(VLOOKUP(A14,'NHẬP ĐƠN'!A:J,10,FALSE),"") | G14: =IF(A14="","",IF(OR(D14>=10000,B14>=5),"⭐ VIP",IF(B14>=3,"💎 Thân thiết","👤 Thường")))
B15: =IF(A15="","",COUNTIFS('NHẬP ĐƠN'!A:A,A15,'NHẬP ĐƠN'!I:I,"<>Đã xoá")) | C15: =IF(A15="","",SUMPRODUCT(('NHẬP ĐƠN'!A$2:A$1000=A15)*('NHẬP ĐƠN'!I$2:I$1000<>"Đã xoá")*('NHẬP ĐƠN'!F$2:F$1000))) | D15: =IF(A15="","",SUMPRODUCT(('NHẬP ĐƠN'!A$2:A$1000=A15)*('NHẬP ĐƠN'!I$2:I$1000<>"Đã xoá")*('NHẬP ĐƠN'!G$2:G$1000)*('NHẬP ĐƠN'!F$2:F$1000))) | E15: =IF(B15>0,D15/B15,"") -> #DIV/0! | F15: =IFERROR(VLOOKUP(A15,'NHẬP ĐƠN'!A:J,10,FALSE),"") | G15: =IF(A15="","",IF(OR(D15>=10000,B15>=5),"⭐ VIP",IF(B15>=3,"💎 Thân thiết","👤 Thường")))
B16: =IF(A16="","",COUNTIFS('NHẬP ĐƠN'!A:A,A16,'NHẬP ĐƠN'!I:I,"<>Đã xoá")) | C16: =IF(A16="","",SUMPRODUCT(('NHẬP ĐƠN'!A$2:A$1000=A16)*('NHẬP ĐƠN'!I$2:I$1000<>"Đã xoá")*('NHẬP ĐƠN'!F$2:F$1000))) | D16: =IF(A16="","",SUMPRODUCT(('NHẬP ĐƠN'!A$2:A$1000=A16)*('NHẬP ĐƠN'!I$2:I$1000<>"Đã xoá")*('NHẬP ĐƠN'!G$2:G$1000)*('NHẬP ĐƠN'!F$2:F$1000))) | E16: =IF(B16>0,D16/B16,"") -> #DIV/0! | F16: =IFERROR(VLOOKUP(A16,'NHẬP ĐƠN'!A:J,10,FALSE),"") | G16: =IF(A16="","",IF(OR(D16>=10000,B16>=5),"⭐ VIP",IF(B16>=3,"💎 Thân thiết","👤 Thường")))
B17: =IF(A17="","",COUNTIFS('NHẬP ĐƠN'!A:A,A17,'NHẬP ĐƠN'!I:I,"<>Đã xoá")) | C17: =IF(A17="","",SUMPRODUCT(('NHẬP ĐƠN'!A$2:A$1000=A17)*('NHẬP ĐƠN'!I$2:I$1000<>"Đã xoá")*('NHẬP ĐƠN'!F$2:F$1000))) | D17: =IF(A17="","",SUMPRODUCT(('NHẬP ĐƠN'!A$2:A$1000=A17)*('NHẬP ĐƠN'!I$2:I$1000<>"Đã xoá")*('NHẬP ĐƠN'!G$2:G$1000)*('NHẬP ĐƠN'!F$2:F$1000))) | E17: =IF(B17>0,D17/B17,"") -> #DIV/0! | F17: =IFERROR(VLOOKUP(A17,'NHẬP ĐƠN'!A:J,10,FALSE),"") | G17: =IF(A17="","",IF(OR(D17>=10000,B17>=5),"⭐ VIP",IF(B17>=3,"💎 Thân thiết","👤 Thường")))
B18: =IF(A18="","",COUNTIFS('NHẬP ĐƠN'!A:A,A18,'NHẬP ĐƠN'!I:I,"<>Đã xoá")) | C18: =IF(A18="","",SUMPRODUCT(('NHẬP ĐƠN'!A$2:A$1000=A18)*('NHẬP ĐƠN'!I$2:I$1000<>"Đã xoá")*('NHẬP ĐƠN'!F$2:F$1000))) | D18: =IF(A18="","",SUMPRODUCT(('NHẬP ĐƠN'!A$2:A$1000=A18)*('NHẬP ĐƠN'!I$2:I$1000<>"Đã xoá")*('NHẬP ĐƠN'!G$2:G$1000)*('NHẬP ĐƠN'!F$2:F$1000))) | E18: =IF(B18>0,D18/B18,"") -> #DIV/0! | F18: =IFERROR(VLOOKUP(A18,'NHẬP ĐƠN'!A:J,10,FALSE),"") | G18: =IF(A18="","",IF(OR(D18>=10000,B18>=5),"⭐ VIP",IF(B18>=3,"💎 Thân thiết","👤 Thường")))
B19: =IF(A19="","",COUNTIFS('NHẬP ĐƠN'!A:A,A19,'NHẬP ĐƠN'!I:I,"<>Đã xoá")) | C19: =IF(A19="","",SUMPRODUCT(('NHẬP ĐƠN'!A$2:A$1000=A19)*('NHẬP ĐƠN'!I$2:I$1000<>"Đã xoá")*('NHẬP ĐƠN'!F$2:F$1000))) | D19: =IF(A19="","",SUMPRODUCT(('NHẬP ĐƠN'!A$2:A$1000=A19)*('NHẬP ĐƠN'!I$2:I$1000<>"Đã xoá")*('NHẬP ĐƠN'!G$2:G$1000)*('NHẬP ĐƠN'!F$2:F$1000))) | E19: =IF(B19>0,D19/B19,"") -> #DIV/0! | F19: =IFERROR(VLOOKUP(A19,'NHẬP ĐƠN'!A:J,10,FALSE),"") | G19: =IF(A19="","",IF(OR(D19>=10000,B19>=5),"⭐ VIP",IF(B19>=3,"💎 Thân thiết","👤 Thường")))
B20: =IF(A20="","",COUNTIFS('NHẬP ĐƠN'!A:A,A20,'NHẬP ĐƠN'!I:I,"<>Đã xoá")) | C20: =IF(A20="","",SUMPRODUCT(('NHẬP ĐƠN'!A$2:A$1000=A20)*('NHẬP ĐƠN'!I$2:I$1000<>"Đã xoá")*('NHẬP ĐƠN'!F$2:F$1000))) | D20: =IF(A20="","",SUMPRODUCT(('NHẬP ĐƠN'!A$2:A$1000=A20)*('NHẬP ĐƠN'!I$2:I$1000<>"Đã xoá")*('NHẬP ĐƠN'!G$2:G$1000)*('NHẬP ĐƠN'!F$2:F$1000))) | E20: =IF(B20>0,D20/B20,"") -> #DIV/0! | F20: =IFERROR(VLOOKUP(A20,'NHẬP ĐƠN'!A:J,10,FALSE),"") | G20: =IF(A20="","",IF(OR(D20>=10000,B20>=5),"⭐ VIP",IF(B20>=3,"💎 Thân thiết","👤 Thường")))
B21: =IF(A21="","",COUNTIFS('NHẬP ĐƠN'!A:A,A21,'NHẬP ĐƠN'!I:I,"<>Đã xoá")) | C21: =IF(A21="","",SUMPRODUCT(('NHẬP ĐƠN'!A$2:A$1000=A21)*('NHẬP ĐƠN'!I$2:I$1000<>"Đã xoá")*('NHẬP ĐƠN'!F$2:F$1000))) | D21: =IF(A21="","",SUMPRODUCT(('NHẬP ĐƠN'!A$2:A$1000=A21)*('NHẬP ĐƠN'!I$2:I$1000<>"Đã xoá")*('NHẬP ĐƠN'!G$2:G$1000)*('NHẬP ĐƠN'!F$2:F$1000))) | E21: =IF(B21>0,D21/B21,"") -> #DIV/0! | F21: =IFERROR(VLOOKUP(A21,'NHẬP ĐƠN'!A:J,10,FALSE),"") | G21: =IF(A21="","",IF(OR(D21>=10000,B21>=5),"⭐ VIP",IF(B21>=3,"💎 Thân thiết","👤 Thường")))
B22: =IF(A22="","",COUNTIFS('NHẬP ĐƠN'!A:A,A22,'NHẬP ĐƠN'!I:I,"<>Đã xoá")) | C22: =IF(A22="","",SUMPRODUCT(('NHẬP ĐƠN'!A$2:A$1000=A22)*('NHẬP ĐƠN'!I$2:I$1000<>"Đã xoá")*('NHẬP ĐƠN'!F$2:F$1000))) | D22: =IF(A22="","",SUMPRODUCT(('NHẬP ĐƠN'!A$2:A$1000=A22)*('NHẬP ĐƠN'!I$2:I$1000<>"Đã xoá")*('NHẬP ĐƠN'!G$2:G$1000)*('NHẬP ĐƠN'!F$2:F$1000))) | E22: =IF(B22>0,D22/B22,"") -> #DIV/0! | F22: =IFERROR(VLOOKUP(A22,'NHẬP ĐƠN'!A:J,10,FALSE),"") | G22: =IF(A22="","",IF(OR(D22>=10000,B22>=5),"⭐ VIP",IF(B22>=3,"💎 Thân thiết","👤 Thường")))
B23: =IF(A23="","",COUNTIFS('NHẬP ĐƠN'!A:A,A23,'NHẬP ĐƠN'!I:I,"<>Đã xoá")) | C23: =IF(A23="","",SUMPRODUCT(('NHẬP ĐƠN'!A$2:A$1000=A23)*('NHẬP ĐƠN'!I$2:I$1000<>"Đã xoá")*('NHẬP ĐƠN'!F$2:F$1000))) | D23: =IF(A23="","",SUMPRODUCT(('NHẬP ĐƠN'!A$2:A$1000=A23)*('NHẬP ĐƠN'!I$2:I$1000<>"Đã xoá")*('NHẬP ĐƠN'!G$2:G$1000)*('NHẬP ĐƠN'!F$2:F$1000))) | E23: =IF(B23>0,D23/B23,"") -> #DIV/0! | F23: =IFERROR(VLOOKUP(A23,'NHẬP ĐƠN'!A:J,10,FALSE),"") | G23: =IF(A23="","",IF(OR(D23>=10000,B23>=5),"⭐ VIP",IF(B23>=3,"💎 Thân thiết","👤 Thường")))
B24: =IF(A24="","",COUNTIFS('NHẬP ĐƠN'!A:A,A24,'NHẬP ĐƠN'!I:I,"<>Đã xoá")) | C24: =IF(A24="","",SUMPRODUCT(('NHẬP ĐƠN'!A$2:A$1000=A24)*('NHẬP ĐƠN'!I$2:I$1000<>"Đã xoá")*('NHẬP ĐƠN'!F$2:F$1000))) | D24: =IF(A24="","",SUMPRODUCT(('NHẬP ĐƠN'!A$2:A$1000=A24)*('NHẬP ĐƠN'!I$2:I$1000<>"Đã xoá")*('NHẬP ĐƠN'!G$2:G$1000)*('NHẬP ĐƠN'!F$2:F$1000))) | E24: =IF(B24>0,D24/B24,"") -> #DIV/0! | F24: =IFERROR(VLOOKUP(A24,'NHẬP ĐƠN'!A:J,10,FALSE),"") | G24: =IF(A24="","",IF(OR(D24>=10000,B24>=5),"⭐ VIP",IF(B24>=3,"💎 Thân thiết","👤 Thường")))
... B29: =IF(A29="","",COUNTIFS('NHẬP ĐƠN'!A:A,A29,'NHẬP ĐƠN'!I:I,"<>Đã xoá")) | C29: =IF(A29="","",SUMPRODUCT(('NHẬP ĐƠN'!A$2:A$1000=A29)*('NHẬP ĐƠN'!I$2:I$1000<>"Đã xoá")*('NHẬP ĐƠN'!F$2:F$1000))) | D29: =IF(A29="","",SUMPRODUCT(('NHẬP ĐƠN'!A$2:A$1000=A29)*('NHẬP ĐƠN'!I$2:I$1000<>"Đã xoá")*('NHẬP ĐƠN'!G$2:G$1000)*('NHẬP ĐƠN'!F$2:F$1000))) | E29: =IF(B29>0,D29/B29,"") -> #DIV/0! | F29: =IFERROR(VLOOKUP(A29,'NHẬP ĐƠN'!A:J,10,FALSE),"") | G29: =IF(A29="","",IF(OR(D29>=10000,B29>=5),"⭐ VIP",IF(B29>=3,"💎 Thân thiết","👤 Thường")))
B30: =IF(A30="","",COUNTIFS('NHẬP ĐƠN'!A:A,A30,'NHẬP ĐƠN'!I:I,"<>Đã xoá")) | C30: =IF(A30="","",SUMPRODUCT(('NHẬP ĐƠN'!A$2:A$1000=A30)*('NHẬP ĐƠN'!I$2:I$1000<>"Đã xoá")*('NHẬP ĐƠN'!F$2:F$1000))) | D30: =IF(A30="","",SUMPRODUCT(('NHẬP ĐƠN'!A$2:A$1000=A30)*('NHẬP ĐƠN'!I$2:I$1000<>"Đã xoá")*('NHẬP ĐƠN'!G$2:G$1000)*('NHẬP ĐƠN'!F$2:F$1000))) | E30: =IF(B30>0,D30/B30,"") -> #DIV/0! | F30: =IFERROR(VLOOKUP(A30,'NHẬP ĐƠN'!A:J,10,FALSE),"") | G30: =IF(A30="","",IF(OR(D30>=10000,B30>=5),"⭐ VIP",IF(B30>=3,"💎 Thân thiết","👤 Thường"))) | H30: 214-0039 | I30: 神奈川県 | J30: 川崎市多摩区 | K30: 栗谷3丁目2番11リズ生田505号
B31: =IF(A31="","",COUNTIFS('NHẬP ĐƠN'!A:A,A31,'NHẬP ĐƠN'!I:I,"<>Đã xoá")) | C31: =IF(A31="","",SUMPRODUCT(('NHẬP ĐƠN'!A$2:A$1000=A31)*('NHẬP ĐƠN'!I$2:I$1000<>"Đã xoá")*('NHẬP ĐƠN'!F$2:F$1000))) | D31: =IF(A31="","",SUMPRODUCT(('NHẬP ĐƠN'!A$2:A$1000=A31)*('NHẬP ĐƠN'!I$2:I$1000<>"Đã xoá")*('NHẬP ĐƠN'!G$2:G$1000)*('NHẬP ĐƠN'!F$2:F$1000))) | E31: =IF(B31>0,D31/B31,"") -> #DIV/0! | F31: =IFERROR(VLOOKUP(A31,'NHẬP ĐƠN'!A:J,10,FALSE),"") | G31: =IF(A31="","",IF(OR(D31>=10000,B31>=5),"⭐ VIP",IF(B31>=3,"💎 Thân thiết","👤 Thường"))) | H31: 574-0025 | I31: 大阪府 | J31: 大東市 | K31: 4-4-42 | L31: 8069613369
B32: =IF(A32="","",COUNTIFS('NHẬP ĐƠN'!A:A,A32,'NHẬP ĐƠN'!I:I,"<>Đã xoá")) | C32: =IF(A32="","",SUMPRODUCT(('NHẬP ĐƠN'!A$2:A$1000=A32)*('NHẬP ĐƠN'!I$2:I$1000<>"Đã xoá")*('NHẬP ĐƠN'!F$2:F$1000))) | D32: =IF(A32="","",SUMPRODUCT(('NHẬP ĐƠN'!A$2:A$1000=A32)*('NHẬP ĐƠN'!I$2:I$1000<>"Đã xoá")*('NHẬP ĐƠN'!G$2:G$1000)*('NHẬP ĐƠN'!F$2:F$1000))) | E32: =IF(B32>0,D32/B32,"") -> #DIV/0! | F32: =IFERROR(VLOOKUP(A32,'NHẬP ĐƠN'!A:J,10,FALSE),"") | G32: =IF(A32="","",IF(OR(D32>=10000,B32>=5),"⭐ VIP",IF(B32>=3,"💎 Thân thiết","👤 Thường")))
B33: =IF(A33="","",COUNTIFS('NHẬP ĐƠN'!A:A,A33,'NHẬP ĐƠN'!I:I,"<>Đã xoá")) | C33: =IF(A33="","",SUMPRODUCT(('NHẬP ĐƠN'!A$2:A$1000=A33)*('NHẬP ĐƠN'!I$2:I$1000<>"Đã xoá")*('NHẬP ĐƠN'!F$2:F$1000))) | D33: =IF(A33="","",SUMPRODUCT(('NHẬP ĐƠN'!A$2:A$1000=A33)*('NHẬP ĐƠN'!I$2:I$1000<>"Đã xoá")*('NHẬP ĐƠN'!G$2:G$1000)*('NHẬP ĐƠN'!F$2:F$1000))) | E33: =IF(B33>0,D33/B33,"") -> #DIV/0! | F33: =IFERROR(VLOOKUP(A33,'NHẬP ĐƠN'!A:J,10,FALSE),"") | G33: =IF(A33="","",IF(OR(D33>=10000,B33>=5),"⭐ VIP",IF(B33>=3,"💎 Thân thiết","👤 Thường"))) | H33: 193-0931 | I33: 東京都 | J33: 八王子市 | K33: 台町1-22-20コーポセイウン102号 | L33: 9030991196
B34: =IF(A34="","",COUNTIFS('NHẬP ĐƠN'!A:A,A34,'NHẬP ĐƠN'!I:I,"<>Đã xoá")) | C34: =IF(A34="","",SUMPRODUCT(('NHẬP ĐƠN'!A$2:A$1000=A34)*('NHẬP ĐƠN'!I$2:I$1000<>"Đã xoá")*('NHẬP ĐƠN'!F$2:F$1000))) | D34: =IF(A34="","",SUMPRODUCT(('NHẬP ĐƠN'!A$2:A$1000=A34)*('NHẬP ĐƠN'!I$2:I$1000<>"Đã xoá")*('NHẬP ĐƠN'!G$2:G$1000)*('NHẬP ĐƠN'!F$2:F$1000))) | E34: =IF(B34>0,D34/B34,"") -> #DIV/0! | F34: =IFERROR(VLOOKUP(A34,'NHẬP ĐƠN'!A:J,10,FALSE),"") | G34: =IF(A34="","",IF(OR(D34>=10000,B34>=5),"⭐ VIP",IF(B34>=3,"💎 Thân thiết","👤 Thường"))) | H34: 168-0071 | I34: 東京都 | J34: 杉並区 | K34: 西3-8-9パレス高井戸 201号室 | L34: 9030991196
B35: =IF(A35="","",COUNTIFS('NHẬP ĐƠN'!A:A,A35,'NHẬP ĐƠN'!I:I,"<>Đã xoá")) | C35: =IF(A35="","",SUMPRODUCT(('NHẬP ĐƠN'!A$2:A$1000=A35)*('NHẬP ĐƠN'!I$2:I$1000<>"Đã xoá")*('NHẬP ĐƠN'!F$2:F$1000))) | D35: =IF(A35="","",SUMPRODUCT(('NHẬP ĐƠN'!A$2:A$1000=A35)*('NHẬP ĐƠN'!I$2:I$1000<>"Đã xoá")*('NHẬP ĐƠN'!G$2:G$1000)*('NHẬP ĐƠN'!F$2:F$1000))) | E35: =IF(B35>0,D35/B35,"") -> #DIV/0! | F35: =IFERROR(VLOOKUP(A35,'NHẬP ĐƠN'!A:J,10,FALSE),"") | G35: =IF(A35="","",IF(OR(D35>=10000,B35>=5),"⭐ VIP",IF(B35>=3,"💎 Thân thiết","👤 Thường"))) | H35: 193-0931 | I35: 東京都 | J35: 八王子市 | K35: 台町1-22-20コーポセイウン102号
B36: =IF(A36="","",COUNTIFS('NHẬP ĐƠN'!A:A,A36,'NHẬP ĐƠN'!I:I,"<>Đã xoá")) | C36: =IF(A36="","",SUMPRODUCT(('NHẬP ĐƠN'!A$2:A$1000=A36)*('NHẬP ĐƠN'!I$2:I$1000<>"Đã xoá")*('NHẬP ĐƠN'!F$2:F$1000))) | D36: =IF(A36="","",SUMPRODUCT(('NHẬP ĐƠN'!A$2:A$1000=A36)*('NHẬP ĐƠN'!I$2:I$1000<>"Đã xoá")*('NHẬP ĐƠN'!G$2:G$1000)*('NHẬP ĐƠN'!F$2:F$1000))) | E36: =IF(B36>0,D36/B36,"") -> #DIV/0! | F36: =IFERROR(VLOOKUP(A36,'NHẬP ĐƠN'!A:J,10,FALSE),"") | G36: =IF(A36="","",IF(OR(D36>=10000,B36>=5),"⭐ VIP",IF(B36>=3,"💎 Thân thiết","👤 Thường")))
B37: =IF(A37="","",COUNTIFS('NHẬP ĐƠN'!A:A,A37,'NHẬP ĐƠN'!I:I,"<>Đã xoá")) | C37: =IF(A37="","",SUMPRODUCT(('NHẬP ĐƠN'!A$2:A$1000=A37)*('NHẬP ĐƠN'!I$2:I$1000<>"Đã xoá")*('NHẬP ĐƠN'!F$2:F$1000))) | D37: =IF(A37="","",SUMPRODUCT(('NHẬP ĐƠN'!A$2:A$1000=A37)*('NHẬP ĐƠN'!I$2:I$1000<>"Đã xoá")*('NHẬP ĐƠN'!G$2:G$1000)*('NHẬP ĐƠN'!F$2:F$1000))) | E37: =IF(B37>0,D37/B37,"") -> #DIV/0! | F37: =IFERROR(VLOOKUP(A37,'NHẬP ĐƠN'!A:J,10,FALSE),"") | G37: =IF(A37="","",IF(OR(D37>=10000,B37>=5),"⭐ VIP",IF(B37>=3,"💎 Thân thiết","👤 Thường")))
B38: =IF(A38="","",COUNTIFS('NHẬP ĐƠN'!A:A,A38,'NHẬP ĐƠN'!I:I,"<>Đã xoá")) | C38: =IF(A38="","",SUMPRODUCT(('NHẬP ĐƠN'!A$2:A$1000=A38)*('NHẬP ĐƠN'!I$2:I$1000<>"Đã xoá")*('NHẬP ĐƠN'!F$2:F$1000))) | D38: =IF(A38="","",SUMPRODUCT(('NHẬP ĐƠN'!A$2:A$1000=A38)*('NHẬP ĐƠN'!I$2:I$1000<>"Đã xoá")*('NHẬP ĐƠN'!G$2:G$1000)*('NHẬP ĐƠN'!F$2:F$1000))) | E38: =IF(B38>0,D38/B38,"") -> #DIV/0! | F38: =IFERROR(VLOOKUP(A38,'NHẬP ĐƠN'!A:J,10,FALSE),"") | G38: =IF(A38="","",IF(OR(D38>=10000,B38>=5),"⭐ VIP",IF(B38>=3,"💎 Thân thiết","👤 Thường")))
B39: =IF(A39="","",COUNTIFS('NHẬP ĐƠN'!A:A,A39,'NHẬP ĐƠN'!I:I,"<>Đã xoá")) | C39: =IF(A39="","",SUMPRODUCT(('NHẬP ĐƠN'!A$2:A$1000=A39)*('NHẬP ĐƠN'!I$2:I$1000<>"Đã xoá")*('NHẬP ĐƠN'!F$2:F$1000))) | D39: =IF(A39="","",SUMPRODUCT(('NHẬP ĐƠN'!A$2:A$1000=A39)*('NHẬP ĐƠN'!I$2:I$1000<>"Đã xoá")*('NHẬP ĐƠN'!G$2:G$1000)*('NHẬP ĐƠN'!F$2:F$1000))) | E39: =IF(B39>0,D39/B39,"") -> #DIV/0! | F39: =IFERROR(VLOOKUP(A39,'NHẬP ĐƠN'!A:J,10,FALSE),"") | G39: =IF(A39="","",IF(OR(D39>=10000,B39>=5),"⭐ VIP",IF(B39>=3,"💎 Thân thiết","👤 Thường")))
B40: =IF(A40="","",COUNTIFS('NHẬP ĐƠN'!A:A,A40,'NHẬP ĐƠN'!I:I,"<>Đã xoá")) | C40: =IF(A40="","",SUMPRODUCT(('NHẬP ĐƠN'!A$2:A$1000=A40)*('NHẬP ĐƠN'!I$2:I$1000<>"Đã xoá")*('NHẬP ĐƠN'!F$2:F$1000))) | D40: =IF(A40="","",SUMPRODUCT(('NHẬP ĐƠN'!A$2:A$1000=A40)*('NHẬP ĐƠN'!I$2:I$1000<>"Đã xoá")*('NHẬP ĐƠN'!G$2:G$1000)*('NHẬP ĐƠN'!F$2:F$1000))) | E40: =IF(B40>0,D40/B40,"") -> #DIV/0! | F40: =IFERROR(VLOOKUP(A40,'NHẬP ĐƠN'!A:J,10,FALSE),"") | G40: =IF(A40="","",IF(OR(D40>=10000,B40>=5),"⭐ VIP",IF(B40>=3,"💎 Thân thiết","👤 Thường")))
B41: =IF(A41="","",COUNTIFS('NHẬP ĐƠN'!A:A,A41,'NHẬP ĐƠN'!I:I,"<>Đã xoá")) | C41: =IF(A41="","",SUMPRODUCT(('NHẬP ĐƠN'!A$2:A$1000=A41)*('NHẬP ĐƠN'!I$2:I$1000<>"Đã xoá")*('NHẬP ĐƠN'!F$2:F$1000))) | D41: =IF(A41="","",SUMPRODUCT(('NHẬP ĐƠN'!A$2:A$1000=A41)*('NHẬP ĐƠN'!I$2:I$1000<>"Đã xoá")*('NHẬP ĐƠN'!G$2:G$1000)*('NHẬP ĐƠN'!F$2:F$1000))) | E41: =IF(B41>0,D41/B41,"") -> #DIV/0! | F41: =IFERROR(VLOOKUP(A41,'NHẬP ĐƠN'!A:J,10,FALSE),"") | G41: =IF(A41="","",IF(OR(D41>=10000,B41>=5),"⭐ VIP",IF(B41>=3,"💎 Thân thiết","👤 Thường"))) | H41: 220-0074 | I41: 神奈川県 | J41: 横浜市西区 | K41: 南浅間町4番地10 TS横浜第一101号 | L41: 9030991196
B42: =IF(A42="","",COUNTIFS('NHẬP ĐƠN'!A:A,A42,'NHẬP ĐƠN'!I:I,"<>Đã xoá")) | C42: =IF(A42="","",SUMPRODUCT(('NHẬP ĐƠN'!A$2:A$1000=A42)*('NHẬP ĐƠN'!I$2:I$1000<>"Đã xoá")*('NHẬP ĐƠN'!F$2:F$1000))) | D42: =IF(A42="","",SUMPRODUCT(('NHẬP ĐƠN'!A$2:A$1000=A42)*('NHẬP ĐƠN'!I$2:I$1000<>"Đã xoá")*('NHẬP ĐƠN'!G$2:G$1000)*('NHẬP ĐƠN'!F$2:F$1000))) | E42: =IF(B42>0,D42/B42,"") -> #DIV/0! | F42: =IFERROR(VLOOKUP(A42,'NHẬP ĐƠN'!A:J,10,FALSE),"") | G42: =IF(A42="","",IF(OR(D42>=10000,B42>=5),"⭐ VIP",IF(B42>=3,"💎 Thân thiết","👤 Thường")))
B43: =IF(A43="","",COUNTIFS('NHẬP ĐƠN'!A:A,A43,'NHẬP ĐƠN'!I:I,"<>Đã xoá")) | C43: =IF(A43="","",SUMPRODUCT(('NHẬP ĐƠN'!A$2:A$1000=A43)*('NHẬP ĐƠN'!I$2:I$1000<>"Đã xoá")*('NHẬP ĐƠN'!F$2:F$1000))) | D43: =IF(A43="","",SUMPRODUCT(('NHẬP ĐƠN'!A$2:A$1000=A43)*('NHẬP ĐƠN'!I$2:I$1000<>"Đã xoá")*('NHẬP ĐƠN'!G$2:G$1000)*('NHẬP ĐƠN'!F$2:F$1000))) | E43: =IF(B43>0,D43/B43,"") -> #DIV/0! | F43: =IFERROR(VLOOKUP(A43,'NHẬP ĐƠN'!A:J,10,FALSE),"") | G43: =IF(A43="","",IF(OR(D43>=10000,B43>=5),"⭐ VIP",IF(B43>=3,"💎 Thân thiết","👤 Thường")))
B44: =IF(A44="","",COUNTIFS('NHẬP ĐƠN'!A:A,A44,'NHẬP ĐƠN'!I:I,"<>Đã xoá")) | C44: =IF(A44="","",SUMPRODUCT(('NHẬP ĐƠN'!A$2:A$1000=A44)*('NHẬP ĐƠN'!I$2:I$1000<>"Đã xoá")*('NHẬP ĐƠN'!F$2:F$1000))) | D44: =IF(A44="","",SUMPRODUCT(('NHẬP ĐƠN'!A$2:A$1000=A44)*('NHẬP ĐƠN'!I$2:I$1000<>"Đã xoá")*('NHẬP ĐƠN'!G$2:G$1000)*('NHẬP ĐƠN'!F$2:F$1000))) | E44: =IF(B44>0,D44/B44,"") -> #DIV/0! | F44: =IFERROR(VLOOKUP(A44,'NHẬP ĐƠN'!A:J,10,FALSE),"") | G44: =IF(A44="","",IF(OR(D44>=10000,B44>=5),"⭐ VIP",IF(B44>=3,"💎 Thân thiết","👤 Thường")))
...

Sheet LỊCH SỬ EMS
A1: Mã EMS | B1: Ngày | C1: Số SKU | D1: Tổng SL | E1: Chi tiết | F1: JSON | G1: Status | H1: Last Check | I1: 17track Raw
A2: EB857015049CN | B2: 46130.528 | C2: 20 | D2: 78 | E2: 9091 S XANH THAN x9, 8558 S TRẮNG x8, M001 39 ĐEN x11, 8558 M XANH NÕN x7, 8558 M HỒNG x5, 8876 S ĐEN x4, 8558 M ĐEN x4, 5709 S XANH NHẠT x4, 5709 M XANH NHẠT x2, 8116 S TRẮNG x4, 8897 M TRẮNG x3, 9091 S TRẮNG x3, 9094 S XANH THAN x2, 8558 S HỒNG x2, 8116 M XANH THAN x2, 8876 M XÁM x1, 8825 S TRẮNG x1, 8116 L XANH THAN x1, 8740 M TRẮNG x4, 8558 M ĐEN x1 | F2: [{"sku":9091,"size":"S","color":"XANH THAN","qty":9},{"sku":8558,"size":"S","color":"TRẮNG","qty":8},{"sku":"M001","size":39,"color":"ĐEN","qty":11},{"sku":8558,"size":"M","color":"XANH NÕN","qty":7},{"sku":8558,"size":"M","color":"HỒNG","qty":5},{"sku":8876,"size":"S","color":"ĐEN","qty":4},{"sku":8558,"size":"M","color":"ĐEN","qty":4},{"sku":5709,"size":"S","color":"XANH NHẠT","qty":4},{"sku":5709,"size":"M","color":"XANH NHẠT","qty":2},{"sku":8116,"size":"S","color":"TRẮNG","qty":4},{"sku":8897,"size":"M","color":"TRẮNG","qty":3},{"sku":9091,"size":"S","color":"TRẮNG","qty":3},{"sku":9094,"size":"S","color":"XANH THAN","qty":2},{"sku":8558,"size":"S","color":"HỒNG","qty":2},{"sku":8116,"size":"M","color":"XANH THAN","qty":2},{"sku":8876,"size":"M","color":"XÁM","qty":1},{"sku":8825,"size":"S","color":"TRẮNG","qty":1},{"sku":8116,"size":"L","color":"XANH THAN","qty":1},{"sku":"8740","size":"M","color":"TRẮNG","qty":4},{"sku":"8558","size":"M","color":"ĐEN","qty":1}] | G2: Về kho | H2: 46130.088 | I2: 配達完了
A3: EB857164343CN | B3: 46132.394 | C3: 15 | D3: 97 | E3: M001 37 ĐEN x15, M006 FZ XÁM x13, M006 FZ ĐEN x15, M006 FZ TRẮNG x11, M006 FZ BE x9, MU01 FZ NÂU NHẠT x5, 8558 M TRẮNG x6, M001 40 ĐEN x4, 8558 M CAM x5, 8558 S ĐEN x4, 8558 S XANH NÕN x3, 8897 S TRẮNG x2, 8558 S CAM x2, 9094 S XÁM x2, M001 36 BE x1 | F3: [{"sku":"M001","size":37,"color":"ĐEN","qty":15},{"sku":"M006","size":"FZ","color":"XÁM","qty":13},{"sku":"M006","size":"FZ","color":"ĐEN","qty":15},{"sku":"M006","size":"FZ","color":"TRẮNG","qty":11},{"sku":"M006","size":"FZ","color":"BE","qty":9},{"sku":"MU01","size":"FZ","color":"NÂU NHẠT","qty":5},{"sku":8558,"size":"M","color":"TRẮNG","qty":6},{"sku":"M001","size":40,"color":"ĐEN","qty":4},{"sku":8558,"size":"M","color":"CAM","qty":5},{"sku":8558,"size":"S","color":"ĐEN","qty":4},{"sku":8558,"size":"S","color":"XANH NÕN","qty":3},{"sku":8897,"size":"S","color":"TRẮNG","qty":2},{"sku":8558,"size":"S","color":"CAM","qty":2},{"sku":9094,"size":"S","color":"XÁM","qty":2},{"sku":"M001","size":"36","color":"BE","qty":1}] | G3: Đã nhập kho
A4: EB857446239CN | B4: 46137.419 | C4: 24 | D4: 33 | E4: M001 38 ĐEN x2, M001 37 ĐEN x4, M001 35 BE x1, 7957 M XÁM x2, 7957 S TRẮNG x2, 7957 M ĐEN x1, 7957 M TRẮNG x1, 7957 S XÁM x1, 7957 S ĐEN x1, M007 FZ NGOCANH x1, M001 36 ĐEN x1, M001 36 BE x1, M001 37 BE x1, M001 38 BE x2, 8876 M ĐEN x2, P651W13129 38 BE x1, PE232WAS632 37 TÍM x1, P661W13310 37 BE x1, P661W13310 37 HỒNG x1, P661W13310 39 HỒNG x1, P661W12375 39 HỒNG x2, P661W12375 38 HỒNG x1, P661W13363 36 NÂU x1, P661W13363 37 NÂU x1 | F4: [{"sku":"M001","size":38,"color":"ĐEN","qty":2},{"sku":"M001","size":37,"color":"ĐEN","qty":4},{"sku":"M001","size":35,"color":"BE","qty":1},{"sku":7957,"size":"M","color":"XÁM","qty":2},{"sku":7957,"size":"S","color":"TRẮNG","qty":2},{"sku":7957,"size":"M","color":"ĐEN","qty":1},{"sku":7957,"size":"M","color":"TRẮNG","qty":1},{"sku":7957,"size":"S","color":"XÁM","qty":1},{"sku":7957,"size":"S","color":"ĐEN","qty":1},{"sku":"M007","size":"FZ","color":"NGOCANH","qty":1},{"sku":"M001","size":"36","color":"ĐEN","qty":1},{"sku":"M001","size":"36","color":"BE","qty":1},{"sku":"M001","size":"37","color":"BE","qty":1},{"sku":"M001","size":"38","color":"BE","qty":2},{"sku":"8876","size":"M","color":"ĐEN","qty":2},{"sku":"P651W13129","size":"38","color":"BE","qty":1},{"sku":"PE232WAS632","size":"37","color":"TÍM","qty":1},{"sku":"P661W13310","size":"37","color":"BE","qty":1},{"sku":"P661W13310","size":"37","color":"HỒNG","qty":1},{"sku":"P661W13310","size":"39","color":"HỒNG","qty":1},{"sku":"P661W12375","size":"39","color":"HỒNG","qty":2},{"sku":"P661W12375","size":"38","color":"HỒNG","qty":1},{"sku":"P661W13363","size":"36","color":"NÂU","qty":1},{"sku":"P661W13363","size":"37","color":"NÂU","qty":1}] | G4: Đã nhập kho
A5: EB857231330CN | B5: 46137.491 | C5: 19 | D5: 51 | E5: M005 38 ĐEN x1, M005 38 NÂU x1, P661W13404 37 NÂU x1, M004 FZ SỌC XANH x2, M004 FZ GẤU HỒNG x1, M004 FZ SỌC HỒNG x2, M004 FZ GẤU XANH x1, 9091 M TRẮNG x2, 9091 L TRẮNG x2, 9091 M XANH THAN x3, 8825 S ĐEN x4, 8876 S TRẮNG x3, TRA1 FZ VÀNG x6, M007 FZ HATHIQUYNH x1, M007 FZ LEYU x1, M001 38 ĐEN x8, M001 35 BE x2, M001 38 BE x3, M001 35 ĐEN x7 | F5: [{"sku":"M005","size":"38","color":"ĐEN","qty":1},{"sku":"M005","size":"38","color":"NÂU","qty":1},{"sku":"P661W13404","size":"37","color":"NÂU","qty":1},{"sku":"M004","size":"FZ","color":"SỌC XANH","qty":2},{"sku":"M004","size":"FZ","color":"GẤU HỒNG","qty":1},{"sku":"M004","size":"FZ","color":"SỌC HỒNG","qty":2},{"sku":"M004","size":"FZ","color":"GẤU XANH","qty":1},{"sku":"9091","size":"M","color":"TRẮNG","qty":2},{"sku":"9091","size":"L","color":"TRẮNG","qty":2},{"sku":"9091","size":"M","color":"XANH THAN","qty":3},{"sku":"8825","size":"S","color":"ĐEN","qty":4},{"sku":"8876","size":"S","color":"TRẮNG","qty":3},{"sku":"TRA1","size":"FZ","color":"VÀNG","qty":6},{"sku":"M007","size":"FZ","color":"HATHIQUYNH","qty":1},{"sku":"M007","size":"FZ","color":"LEYU","qty":1},{"sku":"M001","size":"38","color":"ĐEN","qty":8},{"sku":"M001","size":"35","color":"BE","qty":2},{"sku":"M001","size":"38","color":"BE","qty":3},{"sku":"M001","size":"35","color":"ĐEN","qty":7}] | G5: Đã nhập kho
A6: EB857446344CN | B6: 46137.769 | C6: 24 | D6: 76 | E6: M006 FZ XÁM x8, GIAY1 37 BE x6, M006 FZ TRẮNG x11, 1302 FZ 6 x6, M006 FZ BE x6, 81813 FZ TRẮNG x5, GIAY1 37 ĐEN x4, GIAY1 38 ĐEN x3, 1302 FZ 3 x3, 81813 FZ HỒNG x2, M006 FZ ĐEN x7, 1302 FZ 1 x2, 1302 FZ 9 x2, 81813 FZ ĐEN x1, 81813 FZ XANH NHẠT x1, 81813 FZ VÀNG x1, 1302 FZ 2 x1, 1302 FZ 8 x1, 1302 FZ 5 x1, M007 FZ GIALINH x1, P230MTX362-T800 37 BE x1, P230MTX362-T800 42 ĐEN x1, GIAY2 37 BE x1, GIAY2 39 BE x1 | F6: [{"sku":"M006","size":"FZ","color":"XÁM","qty":8},{"sku":"GIAY1","size":37,"color":"BE","qty":6},{"sku":"M006","size":"FZ","color":"TRẮNG","qty":11},{"sku":1302,"size":"FZ","color":6,"qty":6},{"sku":"M006","size":"FZ","color":"BE","qty":6},{"sku":81813,"size":"FZ","color":"TRẮNG","qty":5},{"sku":"GIAY1","size":37,"color":"ĐEN","qty":4},{"sku":"GIAY1","size":38,"color":"ĐEN","qty":3},{"sku":1302,"size":"FZ","color":3,"qty":3},{"sku":81813,"size":"FZ","color":"HỒNG","qty":2},{"sku":"M006","size":"FZ","color":"ĐEN","qty":7},{"sku":1302,"size":"FZ","color":1,"qty":2},{"sku":1302,"size":"FZ","color":9,"qty":2},{"sku":81813,"size":"FZ","color":"ĐEN","qty":1},{"sku":81813,"size":"FZ","color":"XANH NHẠT","qty":1},{"sku":81813,"size":"FZ","color":"VÀNG","qty":1},{"sku":1302,"size":"FZ","color":2,"qty":1},{"sku":1302,"size":"FZ","color":8,"qty":1},{"sku":1302,"size":"FZ","color":5,"qty":1},{"sku":"M007","size":"FZ","color":"GIALINH","qty":1},{"sku":"P230MTX362-T800","size":"37","color":"BE","qty":1},{"sku":"P230MTX362-T800","size":"42","color":"ĐEN","qty":1},{"sku":"GIAY2","size":"37","color":"BE","qty":1},{"sku":"GIAY2","size":"39","color":"BE","qty":1}] | G6: Đã nhập kho
